2018-01-09 21:06:42,022 ERROR    /home/suyue/opsweb/api/views.py[line:228] tomcat日志获取失败ConnectionError((<urllib3.connection.HTTPConnection object at 0x7f6ac02e4080>, 'Connection to 121.41.23.54 timed out. (connect timeout=30)')) caused by: ConnectTimeoutError((<urllib3.connection.HTTPConnection object at 0x7f6ac02e4080>, 'Connection to 121.41.23.54 timed out. (connect timeout=30)'))
2018-01-10 11:16:29,442 ERROR    /root/opsweb/api/views.py[line:456] nginx日志获取失败ConnectionError((<urllib3.connection.HTTPConnection object at 0x7fc1a9405400>, 'Connection to 121.41.23.54 timed out. (connect timeout=30)')) caused by: ConnectTimeoutError((<urllib3.connection.HTTPConnection object at 0x7fc1a9405400>, 'Connection to 121.41.23.54 timed out. (connect timeout=30)'))
2018-01-10 11:16:29,457 ERROR    /root/opsweb/api/views.py[line:456] nginx日志获取失败ConnectionError((<urllib3.connection.HTTPConnection object at 0x7fc1a940c208>, 'Connection to 121.41.23.54 timed out. (connect timeout=30)')) caused by: ConnectTimeoutError((<urllib3.connection.HTTPConnection object at 0x7fc1a940c208>, 'Connection to 121.41.23.54 timed out. (connect timeout=30)'))
2018-01-10 11:16:29,471 ERROR    /root/opsweb/api/views.py[line:456] nginx日志获取失败ConnectionError((<urllib3.connection.HTTPConnection object at 0x7fc1a8a46da0>, 'Connection to 121.41.23.54 timed out. (connect timeout=30)')) caused by: ConnectTimeoutError((<urllib3.connection.HTTPConnection object at 0x7fc1a8a46da0>, 'Connection to 121.41.23.54 timed out. (connect timeout=30)'))
2018-01-10 11:16:29,514 ERROR    /usr/local/lib/python3.5/dist-packages/django/core/handlers/exception.py[line:135] Internal Server Error: /api/nginxLog/
Traceback (most recent call last):
  File "/usr/local/lib/python3.5/dist-packages/django/core/handlers/exception.py", line 41, in inner
    response = get_response(request)
  File "/usr/local/lib/python3.5/dist-packages/django/core/handlers/base.py", line 198, in _get_response
    "returned None instead." % (callback.__module__, view_name)
ValueError: The view api.views.nginxLog didn't return an HttpResponse object. It returned None instead.
2018-01-10 11:16:29,515 ERROR    /usr/local/lib/python3.5/dist-packages/django/core/handlers/exception.py[line:135] Internal Server Error: /api/nginxLog/
Traceback (most recent call last):
  File "/usr/local/lib/python3.5/dist-packages/django/core/handlers/exception.py", line 41, in inner
    response = get_response(request)
  File "/usr/local/lib/python3.5/dist-packages/django/core/handlers/base.py", line 198, in _get_response
    "returned None instead." % (callback.__module__, view_name)
ValueError: The view api.views.nginxLog didn't return an HttpResponse object. It returned None instead.
2018-01-10 11:16:29,515 ERROR    /usr/local/lib/python3.5/dist-packages/django/core/handlers/exception.py[line:135] Internal Server Error: /api/nginxLog/
Traceback (most recent call last):
  File "/usr/local/lib/python3.5/dist-packages/django/core/handlers/exception.py", line 41, in inner
    response = get_response(request)
  File "/usr/local/lib/python3.5/dist-packages/django/core/handlers/base.py", line 198, in _get_response
    "returned None instead." % (callback.__module__, view_name)
ValueError: The view api.views.nginxLog didn't return an HttpResponse object. It returned None instead.
2018-01-10 11:16:29,573 ERROR    /usr/local/lib/python3.5/dist-packages/django/core/servers/basehttp.py[line:124] "POST /api/nginxLog/ HTTP/1.0" 500 27
2018-01-10 11:16:29,576 ERROR    /usr/local/lib/python3.5/dist-packages/django/core/servers/basehttp.py[line:124] "POST /api/nginxLog/ HTTP/1.0" 500 27
2018-01-10 11:16:29,579 ERROR    /usr/local/lib/python3.5/dist-packages/django/core/servers/basehttp.py[line:124] "POST /api/nginxLog/ HTTP/1.0" 500 27
2018-01-10 17:12:05,052 ERROR    /usr/local/lib/python3.5/dist-packages/django/core/handlers/exception.py[line:135] Internal Server Error: /api/deployBackUp/
Traceback (most recent call last):
  File "/usr/local/lib/python3.5/dist-packages/django/core/handlers/exception.py", line 41, in inner
    response = get_response(request)
  File "/usr/local/lib/python3.5/dist-packages/django/core/handlers/base.py", line 187, in _get_response
    response = self.process_exception_by_middleware(e, request)
  File "/usr/local/lib/python3.5/dist-packages/django/core/handlers/base.py", line 185, in _get_response
    response = wrapped_callback(request, *callback_args, **callback_kwargs)
  File "/root/opsweb/api/deploy.py", line 577, in deployOrBackUp
    cmd="cd /tmp && curl -O "+conf_dit['file_download_url']+fileInfo.filePath.split('static/appFile')[-1]
TypeError: Can't convert 'list' object to str implicitly
2018-01-10 17:12:05,835 ERROR    /usr/local/lib/python3.5/dist-packages/django/core/servers/basehttp.py[line:124] "POST /api/deployBackUp/ HTTP/1.0" 500 27
2018-01-10 17:12:35,016 ERROR    /usr/local/lib/python3.5/dist-packages/django/core/handlers/exception.py[line:135] Internal Server Error: /api/deployBackUp/
Traceback (most recent call last):
  File "/usr/local/lib/python3.5/dist-packages/django/core/handlers/exception.py", line 41, in inner
    response = get_response(request)
  File "/usr/local/lib/python3.5/dist-packages/django/core/handlers/base.py", line 187, in _get_response
    response = self.process_exception_by_middleware(e, request)
  File "/usr/local/lib/python3.5/dist-packages/django/core/handlers/base.py", line 185, in _get_response
    response = wrapped_callback(request, *callback_args, **callback_kwargs)
  File "/root/opsweb/api/deploy.py", line 577, in deployOrBackUp
    cmd="cd /tmp && curl -O "+conf_dit['file_download_url']+fileInfo.filePath.split('static/appFile')[0]
TypeError: Can't convert 'list' object to str implicitly
2018-01-10 17:12:35,035 ERROR    /usr/local/lib/python3.5/dist-packages/django/core/servers/basehttp.py[line:124] "POST /api/deployBackUp/ HTTP/1.0" 500 27
2018-01-10 17:25:59,592 ERROR    /usr/local/lib/python3.5/dist-packages/django/core/handlers/exception.py[line:135] Internal Server Error: /api/deployBackUp/
Traceback (most recent call last):
  File "/usr/local/lib/python3.5/dist-packages/django/core/handlers/exception.py", line 41, in inner
    response = get_response(request)
  File "/usr/local/lib/python3.5/dist-packages/django/core/handlers/base.py", line 187, in _get_response
    response = self.process_exception_by_middleware(e, request)
  File "/usr/local/lib/python3.5/dist-packages/django/core/handlers/base.py", line 185, in _get_response
    response = wrapped_callback(request, *callback_args, **callback_kwargs)
  File "/root/opsweb/api/deploy.py", line 578, in deployOrBackUp
    cmd+="cd /tmp && if [ -f %s ];then "(fileInfo.fileName)
TypeError: 'str' object is not callable
2018-01-10 17:25:59,604 ERROR    /usr/local/lib/python3.5/dist-packages/django/core/servers/basehttp.py[line:124] "POST /api/deployBackUp/ HTTP/1.0" 500 27
2018-01-10 17:42:48,867 ERROR    /usr/local/lib/python3.5/dist-packages/django/core/handlers/exception.py[line:135] Internal Server Error: /api/deployBackUp/
Traceback (most recent call last):
  File "/usr/local/lib/python3.5/dist-packages/django/core/handlers/exception.py", line 41, in inner
    response = get_response(request)
  File "/usr/local/lib/python3.5/dist-packages/django/core/handlers/base.py", line 187, in _get_response
    response = self.process_exception_by_middleware(e, request)
  File "/usr/local/lib/python3.5/dist-packages/django/core/handlers/base.py", line 185, in _get_response
    response = wrapped_callback(request, *callback_args, **callback_kwargs)
  File "/root/opsweb/api/deploy.py", line 581, in deployOrBackUp
    "filepath":app.appPath}
KeyError: 'fileName'
2018-01-10 17:42:48,889 ERROR    /usr/local/lib/python3.5/dist-packages/django/core/servers/basehttp.py[line:124] "POST /api/deployBackUp/ HTTP/1.0" 500 27
2018-01-10 17:43:25,391 ERROR    /usr/local/lib/python3.5/dist-packages/django/core/handlers/exception.py[line:135] Internal Server Error: /api/deployBackUp/
Traceback (most recent call last):
  File "/usr/local/lib/python3.5/dist-packages/django/core/handlers/exception.py", line 41, in inner
    response = get_response(request)
  File "/usr/local/lib/python3.5/dist-packages/django/core/handlers/base.py", line 187, in _get_response
    response = self.process_exception_by_middleware(e, request)
  File "/usr/local/lib/python3.5/dist-packages/django/core/handlers/base.py", line 185, in _get_response
    response = wrapped_callback(request, *callback_args, **callback_kwargs)
  File "/root/opsweb/api/deploy.py", line 581, in deployOrBackUp
    "filepath":app.appPath}
KeyError: 'filePath'
2018-01-10 17:43:25,405 ERROR    /usr/local/lib/python3.5/dist-packages/django/core/servers/basehttp.py[line:124] "POST /api/deployBackUp/ HTTP/1.0" 500 27
2018-01-10 18:02:32,075 WARNING  /usr/local/lib/python3.5/dist-packages/django/core/servers/basehttp.py[line:124] "GET //2018-01-02/o_1c2r32o8bcmu12suht1d341v381v.jpg HTTP/1.0" 403 0
2018-01-10 18:03:24,211 WARNING  /usr/local/lib/python3.5/dist-packages/django/core/servers/basehttp.py[line:124] "GET //2018-01-02/o_1c2r32o8bcmu12suht1d341v381v.jpg HTTP/1.0" 403 0
2018-01-10 18:03:50,662 WARNING  /usr/local/lib/python3.5/dist-packages/django/core/servers/basehttp.py[line:124] "GET //2018-01-02/o_1c2r32o8bcmu12suht1d341v381v.jpg HTTP/1.0" 403 0
2018-01-10 18:04:11,642 WARNING  /usr/local/lib/python3.5/dist-packages/django/core/servers/basehttp.py[line:124] "GET //2018-01-02/o_1c2r32o8bcmu12suht1d341v381v.jpg HTTP/1.0" 403 0
2018-01-10 18:06:20,613 WARNING  /usr/local/lib/python3.5/dist-packages/django/core/servers/basehttp.py[line:124] "GET //2018-01-02/o_1c2r32o8bcmu12suht1d341v381v.jpg HTTP/1.0" 403 0
2018-01-10 18:06:31,817 WARNING  /usr/local/lib/python3.5/dist-packages/django/core/servers/basehttp.py[line:124] "GET //2018-01-02/o_1c2r32o8bcmu12suht1d341v381v.jpg HTTP/1.0" 403 0
2018-01-10 18:06:55,170 WARNING  /usr/local/lib/python3.5/dist-packages/django/core/servers/basehttp.py[line:124] "GET //2018-01-02/o_1c2r32o8bcmu12suht1d341v381v.jpg HTTP/1.0" 403 0
2018-01-10 18:06:56,996 WARNING  /usr/local/lib/python3.5/dist-packages/django/core/servers/basehttp.py[line:124] "GET //2018-01-02/o_1c2r32o8bcmu12suht1d341v381v.jpg HTTP/1.0" 403 0
2018-01-10 18:06:57,619 WARNING  /usr/local/lib/python3.5/dist-packages/django/core/servers/basehttp.py[line:124] "GET //2018-01-02/o_1c2r32o8bcmu12suht1d341v381v.jpg HTTP/1.0" 403 0
2018-01-10 18:06:58,221 WARNING  /usr/local/lib/python3.5/dist-packages/django/core/servers/basehttp.py[line:124] "GET //2018-01-02/o_1c2r32o8bcmu12suht1d341v381v.jpg HTTP/1.0" 403 0
2018-01-10 18:07:21,401 WARNING  /usr/local/lib/python3.5/dist-packages/django/core/servers/basehttp.py[line:124] "GET //2018-01-02/o_1c2r32o8bcmu12suht1d341v381v.jpg HTTP/1.0" 403 0
2018-01-10 19:27:23,638 ERROR    /usr/local/lib/python3.5/dist-packages/django/core/handlers/exception.py[line:135] Internal Server Error: /monitor/abnormal/
Traceback (most recent call last):
  File "/usr/local/lib/python3.5/dist-packages/django/core/handlers/exception.py", line 41, in inner
    response = get_response(request)
  File "/usr/local/lib/python3.5/dist-packages/django/core/handlers/base.py", line 187, in _get_response
    response = self.process_exception_by_middleware(e, request)
  File "/usr/local/lib/python3.5/dist-packages/django/core/handlers/base.py", line 185, in _get_response
    response = wrapped_callback(request, *callback_args, **callback_kwargs)
  File "/home/suyue/opsweb/monitor/views.py", line 157, in abnormal
    print(time.mktime(time.time()))
TypeError: Tuple or struct_time argument required
2018-01-10 19:27:23,789 ERROR    /usr/local/lib/python3.5/dist-packages/django/core/servers/basehttp.py[line:124] "GET /monitor/abnormal/ HTTP/1.0" 500 27
2018-01-10 21:04:00,222 ERROR    /usr/local/lib/python3.5/dist-packages/django/core/handlers/exception.py[line:135] Internal Server Error: /monitor/abnormal/
Traceback (most recent call last):
  File "/usr/local/lib/python3.5/dist-packages/django/core/handlers/exception.py", line 41, in inner
    response = get_response(request)
  File "/usr/local/lib/python3.5/dist-packages/django/core/handlers/base.py", line 187, in _get_response
    response = self.process_exception_by_middleware(e, request)
  File "/usr/local/lib/python3.5/dist-packages/django/core/handlers/base.py", line 185, in _get_response
    response = wrapped_callback(request, *callback_args, **callback_kwargs)
  File "/home/suyue/opsweb/monitor/views.py", line 129, in abnormal
    ac.valueCheck()
  File "/home/suyue/opsweb/utils/abNormalCheck.py", line 25, in valueCheck
    print("总共耗时%d"%int(time.time())-s)
TypeError: unsupported operand type(s) for -: 'str' and 'int'
2018-01-10 21:04:00,257 ERROR    /usr/local/lib/python3.5/dist-packages/django/core/servers/basehttp.py[line:124] "GET /monitor/abnormal/ HTTP/1.0" 500 27
2018-01-10 21:06:43,833 ERROR    /usr/local/lib/python3.5/dist-packages/django/core/handlers/exception.py[line:135] Internal Server Error: /monitor/abnormal/
Traceback (most recent call last):
  File "/usr/local/lib/python3.5/dist-packages/django/core/handlers/exception.py", line 41, in inner
    response = get_response(request)
  File "/usr/local/lib/python3.5/dist-packages/django/core/handlers/base.py", line 187, in _get_response
    response = self.process_exception_by_middleware(e, request)
  File "/usr/local/lib/python3.5/dist-packages/django/core/handlers/base.py", line 185, in _get_response
    response = wrapped_callback(request, *callback_args, **callback_kwargs)
  File "/home/suyue/opsweb/monitor/views.py", line 129, in abnormal
    ac.valueCheck()
  File "/home/suyue/opsweb/utils/abNormalCheck.py", line 24, in valueCheck
    pool.apply_async(self.__historyGet,item)
  File "/usr/lib/python3.5/multiprocessing/pool.py", line 322, in apply_async
    raise ValueError("Pool not running")
ValueError: Pool not running
2018-01-10 21:06:43,978 ERROR    /usr/local/lib/python3.5/dist-packages/django/core/servers/basehttp.py[line:124] "GET /monitor/abnormal/ HTTP/1.0" 500 27
2018-01-10 21:07:43,689 ERROR    /usr/local/lib/python3.5/dist-packages/django/core/handlers/exception.py[line:135] Internal Server Error: /monitor/abnormal/
Traceback (most recent call last):
  File "/usr/local/lib/python3.5/dist-packages/django/core/handlers/exception.py", line 41, in inner
    response = get_response(request)
  File "/usr/local/lib/python3.5/dist-packages/django/core/handlers/base.py", line 187, in _get_response
    response = self.process_exception_by_middleware(e, request)
  File "/usr/local/lib/python3.5/dist-packages/django/core/handlers/base.py", line 185, in _get_response
    response = wrapped_callback(request, *callback_args, **callback_kwargs)
  File "/home/suyue/opsweb/monitor/views.py", line 129, in abnormal
    ac.valueCheck()
  File "/home/suyue/opsweb/utils/abNormalCheck.py", line 24, in valueCheck
    pool.apply_async(self.__historyGet,(item))
  File "/usr/lib/python3.5/multiprocessing/pool.py", line 322, in apply_async
    raise ValueError("Pool not running")
ValueError: Pool not running
2018-01-10 21:07:43,726 ERROR    /usr/local/lib/python3.5/dist-packages/django/core/servers/basehttp.py[line:124] "GET /monitor/abnormal/ HTTP/1.0" 500 27
2018-01-10 21:08:01,995 ERROR    /usr/local/lib/python3.5/dist-packages/django/core/handlers/exception.py[line:135] Internal Server Error: /monitor/abnormal/
Traceback (most recent call last):
  File "/usr/local/lib/python3.5/dist-packages/django/core/handlers/exception.py", line 41, in inner
    response = get_response(request)
  File "/usr/local/lib/python3.5/dist-packages/django/core/handlers/base.py", line 187, in _get_response
    response = self.process_exception_by_middleware(e, request)
  File "/usr/local/lib/python3.5/dist-packages/django/core/handlers/base.py", line 185, in _get_response
    response = wrapped_callback(request, *callback_args, **callback_kwargs)
  File "/home/suyue/opsweb/monitor/views.py", line 129, in abnormal
    ac.valueCheck()
  File "/home/suyue/opsweb/utils/abNormalCheck.py", line 24, in valueCheck
    pool.apply_async(self.__historyGet,(item,))
  File "/usr/lib/python3.5/multiprocessing/pool.py", line 322, in apply_async
    raise ValueError("Pool not running")
ValueError: Pool not running
2018-01-10 21:08:02,014 ERROR    /usr/local/lib/python3.5/dist-packages/django/core/servers/basehttp.py[line:124] "GET /monitor/abnormal/ HTTP/1.0" 500 27
2018-01-10 21:08:29,901 ERROR    /usr/local/lib/python3.5/dist-packages/django/core/handlers/exception.py[line:135] Internal Server Error: /monitor/abnormal/
Traceback (most recent call last):
  File "/usr/local/lib/python3.5/dist-packages/django/core/handlers/exception.py", line 41, in inner
    response = get_response(request)
  File "/usr/local/lib/python3.5/dist-packages/django/core/handlers/base.py", line 187, in _get_response
    response = self.process_exception_by_middleware(e, request)
  File "/usr/local/lib/python3.5/dist-packages/django/core/handlers/base.py", line 185, in _get_response
    response = wrapped_callback(request, *callback_args, **callback_kwargs)
  File "/home/suyue/opsweb/monitor/views.py", line 129, in abnormal
    ac.valueCheck()
  File "/home/suyue/opsweb/utils/abNormalCheck.py", line 24, in valueCheck
    pool.apply_async(self.__historyGet,(item,))
  File "/usr/lib/python3.5/multiprocessing/pool.py", line 322, in apply_async
    raise ValueError("Pool not running")
ValueError: Pool not running
2018-01-10 21:08:29,919 ERROR    /usr/local/lib/python3.5/dist-packages/django/core/servers/basehttp.py[line:124] "GET /monitor/abnormal/ HTTP/1.0" 500 27
2018-01-10 21:25:20,074 ERROR    /usr/local/lib/python3.5/dist-packages/django/core/handlers/exception.py[line:135] Internal Server Error: /monitor/abnormal/
Traceback (most recent call last):
  File "/usr/local/lib/python3.5/dist-packages/django/core/handlers/exception.py", line 41, in inner
    response = get_response(request)
  File "/usr/local/lib/python3.5/dist-packages/django/core/handlers/base.py", line 187, in _get_response
    response = self.process_exception_by_middleware(e, request)
  File "/usr/local/lib/python3.5/dist-packages/django/core/handlers/base.py", line 185, in _get_response
    response = wrapped_callback(request, *callback_args, **callback_kwargs)
  File "/home/suyue/opsweb/monitor/views.py", line 129, in abnormal
    ac.valueCheck()
  File "/home/suyue/opsweb/utils/abNormalCheck.py", line 29, in valueCheck
    print(res.get())
  File "/usr/lib/python3.5/multiprocessing/pool.py", line 608, in get
    raise self._value
  File "/usr/lib/python3.5/multiprocessing/pool.py", line 385, in _handle_tasks
    put(task)
  File "/usr/lib/python3.5/multiprocessing/connection.py", line 206, in send
    self._send_bytes(ForkingPickler.dumps(obj))
  File "/usr/lib/python3.5/multiprocessing/reduction.py", line 50, in dumps
    cls(buf, protocol).dump(obj)
TypeError: 'ZabbixAPIObjectClass' object is not callable
2018-01-10 21:25:20,131 ERROR    /usr/local/lib/python3.5/dist-packages/django/core/servers/basehttp.py[line:124] "GET /monitor/abnormal/ HTTP/1.0" 500 27
2018-01-10 21:47:27,019 ERROR    /home/suyue/opsweb/api/views.py[line:228] tomcat日志获取失败ConnectionError((<urllib3.connection.HTTPConnection object at 0x7f7e9c543da0>, 'Connection to 121.41.23.54 timed out. (connect timeout=30)')) caused by: ConnectTimeoutError((<urllib3.connection.HTTPConnection object at 0x7f7e9c543da0>, 'Connection to 121.41.23.54 timed out. (connect timeout=30)'))
2018-01-10 22:09:31,029 ERROR    /usr/local/lib/python3.5/dist-packages/django/core/handlers/exception.py[line:135] Internal Server Error: /monitor/abnormal/
Traceback (most recent call last):
  File "/usr/local/lib/python3.5/dist-packages/django/core/handlers/exception.py", line 41, in inner
    response = get_response(request)
  File "/usr/local/lib/python3.5/dist-packages/django/core/handlers/base.py", line 187, in _get_response
    response = self.process_exception_by_middleware(e, request)
  File "/usr/local/lib/python3.5/dist-packages/django/core/handlers/base.py", line 185, in _get_response
    response = wrapped_callback(request, *callback_args, **callback_kwargs)
  File "/home/suyue/opsweb/monitor/views.py", line 129, in abnormal
    ac.valueCheck()
  File "/home/suyue/opsweb/utils/abNormalCheck.py", line 27, in valueCheck
    pool.join(10)
TypeError: join() takes 1 positional argument but 2 were given
2018-01-10 22:09:31,074 ERROR    /usr/local/lib/python3.5/dist-packages/django/core/servers/basehttp.py[line:124] "GET /monitor/abnormal/ HTTP/1.0" 500 27
2018-01-10 22:34:59,966 ERROR    /usr/local/lib/python3.5/dist-packages/django/core/handlers/exception.py[line:135] Internal Server Error: /monitor/abnormal/
Traceback (most recent call last):
  File "/usr/local/lib/python3.5/dist-packages/django/core/handlers/exception.py", line 41, in inner
    response = get_response(request)
  File "/usr/local/lib/python3.5/dist-packages/django/core/handlers/base.py", line 187, in _get_response
    response = self.process_exception_by_middleware(e, request)
  File "/usr/local/lib/python3.5/dist-packages/django/core/handlers/base.py", line 185, in _get_response
    response = wrapped_callback(request, *callback_args, **callback_kwargs)
  File "/home/suyue/opsweb/monitor/views.py", line 129, in abnormal
    ac.valueCheck()
  File "/home/suyue/opsweb/utils/abNormalCheck.py", line 24, in valueCheck
    pool.apply_async(historyGet,(item,itemdata))
  File "/usr/lib/python3.5/multiprocessing/pool.py", line 322, in apply_async
    raise ValueError("Pool not running")
ValueError: Pool not running
2018-01-10 22:35:00,131 ERROR    /usr/local/lib/python3.5/dist-packages/django/core/servers/basehttp.py[line:124] "GET /monitor/abnormal/ HTTP/1.0" 500 27
2018-01-10 22:35:07,112 ERROR    /usr/local/lib/python3.5/dist-packages/django/core/handlers/exception.py[line:135] Internal Server Error: /monitor/abnormal/
Traceback (most recent call last):
  File "/usr/local/lib/python3.5/dist-packages/django/core/handlers/exception.py", line 41, in inner
    response = get_response(request)
  File "/usr/local/lib/python3.5/dist-packages/django/core/handlers/base.py", line 187, in _get_response
    response = self.process_exception_by_middleware(e, request)
  File "/usr/local/lib/python3.5/dist-packages/django/core/handlers/base.py", line 185, in _get_response
    response = wrapped_callback(request, *callback_args, **callback_kwargs)
  File "/home/suyue/opsweb/monitor/views.py", line 129, in abnormal
    ac.valueCheck()
  File "/home/suyue/opsweb/utils/abNormalCheck.py", line 24, in valueCheck
    pool.apply_async(historyGet,(item,itemdata))
  File "/usr/lib/python3.5/multiprocessing/pool.py", line 322, in apply_async
    raise ValueError("Pool not running")
ValueError: Pool not running
2018-01-10 22:35:07,118 ERROR    /usr/local/lib/python3.5/dist-packages/django/core/servers/basehttp.py[line:124] "GET /monitor/abnormal/ HTTP/1.0" 500 27
2018-01-10 22:35:13,849 ERROR    /usr/local/lib/python3.5/dist-packages/django/core/handlers/exception.py[line:135] Internal Server Error: /monitor/abnormal/
Traceback (most recent call last):
  File "/usr/local/lib/python3.5/dist-packages/django/core/handlers/exception.py", line 41, in inner
    response = get_response(request)
  File "/usr/local/lib/python3.5/dist-packages/django/core/handlers/base.py", line 187, in _get_response
    response = self.process_exception_by_middleware(e, request)
  File "/usr/local/lib/python3.5/dist-packages/django/core/handlers/base.py", line 185, in _get_response
    response = wrapped_callback(request, *callback_args, **callback_kwargs)
  File "/home/suyue/opsweb/monitor/views.py", line 129, in abnormal
    ac.valueCheck()
  File "/home/suyue/opsweb/utils/abNormalCheck.py", line 24, in valueCheck
    pool.apply_async(historyGet,(item,itemdata))
  File "/usr/lib/python3.5/multiprocessing/pool.py", line 322, in apply_async
    raise ValueError("Pool not running")
ValueError: Pool not running
2018-01-10 22:35:13,852 ERROR    /usr/local/lib/python3.5/dist-packages/django/core/servers/basehttp.py[line:124] "GET /monitor/abnormal/ HTTP/1.0" 500 27
2018-01-10 22:35:20,735 ERROR    /usr/local/lib/python3.5/dist-packages/django/core/handlers/exception.py[line:135] Internal Server Error: /monitor/abnormal/
Traceback (most recent call last):
  File "/usr/local/lib/python3.5/dist-packages/django/core/handlers/exception.py", line 41, in inner
    response = get_response(request)
  File "/usr/local/lib/python3.5/dist-packages/django/core/handlers/base.py", line 187, in _get_response
    response = self.process_exception_by_middleware(e, request)
  File "/usr/local/lib/python3.5/dist-packages/django/core/handlers/base.py", line 185, in _get_response
    response = wrapped_callback(request, *callback_args, **callback_kwargs)
  File "/home/suyue/opsweb/monitor/views.py", line 129, in abnormal
    ac.valueCheck()
  File "/home/suyue/opsweb/utils/abNormalCheck.py", line 24, in valueCheck
    pool.apply_async(historyGet,(item,itemdata))
  File "/usr/lib/python3.5/multiprocessing/pool.py", line 322, in apply_async
    raise ValueError("Pool not running")
ValueError: Pool not running
2018-01-10 22:35:20,738 ERROR    /usr/local/lib/python3.5/dist-packages/django/core/servers/basehttp.py[line:124] "GET /monitor/abnormal/ HTTP/1.0" 500 27
2018-01-10 22:35:28,208 ERROR    /usr/local/lib/python3.5/dist-packages/django/core/handlers/exception.py[line:135] Internal Server Error: /monitor/abnormal/
Traceback (most recent call last):
  File "/usr/local/lib/python3.5/dist-packages/django/core/handlers/exception.py", line 41, in inner
    response = get_response(request)
  File "/usr/local/lib/python3.5/dist-packages/django/core/handlers/base.py", line 187, in _get_response
    response = self.process_exception_by_middleware(e, request)
  File "/usr/local/lib/python3.5/dist-packages/django/core/handlers/base.py", line 185, in _get_response
    response = wrapped_callback(request, *callback_args, **callback_kwargs)
  File "/home/suyue/opsweb/monitor/views.py", line 129, in abnormal
    ac.valueCheck()
  File "/home/suyue/opsweb/utils/abNormalCheck.py", line 24, in valueCheck
    pool.apply_async(historyGet,(item,itemdata))
  File "/usr/lib/python3.5/multiprocessing/pool.py", line 322, in apply_async
    raise ValueError("Pool not running")
ValueError: Pool not running
2018-01-10 22:35:28,223 ERROR    /usr/local/lib/python3.5/dist-packages/django/core/servers/basehttp.py[line:124] "GET /monitor/abnormal/ HTTP/1.0" 500 27
2018-01-10 22:35:31,670 ERROR    /usr/local/lib/python3.5/dist-packages/django/core/handlers/exception.py[line:135] Internal Server Error: /monitor/abnormal/
Traceback (most recent call last):
  File "/usr/local/lib/python3.5/dist-packages/django/core/handlers/exception.py", line 41, in inner
    response = get_response(request)
  File "/usr/local/lib/python3.5/dist-packages/django/core/handlers/base.py", line 187, in _get_response
    response = self.process_exception_by_middleware(e, request)
  File "/usr/local/lib/python3.5/dist-packages/django/core/handlers/base.py", line 185, in _get_response
    response = wrapped_callback(request, *callback_args, **callback_kwargs)
  File "/home/suyue/opsweb/monitor/views.py", line 129, in abnormal
    ac.valueCheck()
  File "/home/suyue/opsweb/utils/abNormalCheck.py", line 24, in valueCheck
    pool.apply_async(historyGet,(item,itemdata))
  File "/usr/lib/python3.5/multiprocessing/pool.py", line 322, in apply_async
    raise ValueError("Pool not running")
ValueError: Pool not running
2018-01-10 22:35:31,675 ERROR    /usr/local/lib/python3.5/dist-packages/django/core/servers/basehttp.py[line:124] "GET /monitor/abnormal/ HTTP/1.0" 500 27
2018-01-10 22:36:01,792 ERROR    /usr/local/lib/python3.5/dist-packages/django/core/handlers/exception.py[line:135] Internal Server Error: /monitor/abnormal/
Traceback (most recent call last):
  File "/usr/local/lib/python3.5/dist-packages/django/core/handlers/exception.py", line 41, in inner
    response = get_response(request)
  File "/usr/local/lib/python3.5/dist-packages/django/core/handlers/base.py", line 187, in _get_response
    response = self.process_exception_by_middleware(e, request)
  File "/usr/local/lib/python3.5/dist-packages/django/core/handlers/base.py", line 185, in _get_response
    response = wrapped_callback(request, *callback_args, **callback_kwargs)
  File "/home/suyue/opsweb/monitor/views.py", line 129, in abnormal
    ac.valueCheck()
  File "/home/suyue/opsweb/utils/abNormalCheck.py", line 24, in valueCheck
    pool.apply_async(historyGet,(item,itemdata))
  File "/usr/lib/python3.5/multiprocessing/pool.py", line 322, in apply_async
    raise ValueError("Pool not running")
ValueError: Pool not running
2018-01-10 22:36:01,804 ERROR    /usr/local/lib/python3.5/dist-packages/django/core/servers/basehttp.py[line:124] "GET /monitor/abnormal/ HTTP/1.0" 500 27
2018-01-10 22:36:42,746 ERROR    /usr/local/lib/python3.5/dist-packages/django/core/handlers/exception.py[line:135] Internal Server Error: /monitor/abnormal/
Traceback (most recent call last):
  File "/usr/local/lib/python3.5/dist-packages/django/core/handlers/exception.py", line 41, in inner
    response = get_response(request)
  File "/usr/local/lib/python3.5/dist-packages/django/core/handlers/base.py", line 187, in _get_response
    response = self.process_exception_by_middleware(e, request)
  File "/usr/local/lib/python3.5/dist-packages/django/core/handlers/base.py", line 185, in _get_response
    response = wrapped_callback(request, *callback_args, **callback_kwargs)
  File "/home/suyue/opsweb/monitor/views.py", line 129, in abnormal
    ac.valueCheck()
  File "/home/suyue/opsweb/utils/abNormalCheck.py", line 24, in valueCheck
    pool.apply_async(historyGet,(item,itemdata))
  File "/usr/lib/python3.5/multiprocessing/pool.py", line 322, in apply_async
    raise ValueError("Pool not running")
ValueError: Pool not running
2018-01-10 22:36:42,771 ERROR    /usr/local/lib/python3.5/dist-packages/django/core/servers/basehttp.py[line:124] "GET /monitor/abnormal/ HTTP/1.0" 500 27
2018-01-10 22:41:22,255 ERROR    /usr/local/lib/python3.5/dist-packages/django/core/handlers/exception.py[line:135] Internal Server Error: /monitor/abnormal/
Traceback (most recent call last):
  File "/usr/local/lib/python3.5/dist-packages/django/core/handlers/exception.py", line 41, in inner
    response = get_response(request)
  File "/usr/local/lib/python3.5/dist-packages/django/core/handlers/base.py", line 187, in _get_response
    response = self.process_exception_by_middleware(e, request)
  File "/usr/local/lib/python3.5/dist-packages/django/core/handlers/base.py", line 185, in _get_response
    response = wrapped_callback(request, *callback_args, **callback_kwargs)
  File "/home/suyue/opsweb/monitor/views.py", line 129, in abnormal
    ac.valueCheck()
  File "/home/suyue/opsweb/utils/abNormalCheck.py", line 24, in valueCheck
    pool.apply_async(historyGet,(item,itemdata))
  File "/usr/lib/python3.5/multiprocessing/pool.py", line 322, in apply_async
    raise ValueError("Pool not running")
ValueError: Pool not running
2018-01-10 22:41:22,279 ERROR    /usr/local/lib/python3.5/dist-packages/django/core/servers/basehttp.py[line:124] "GET /monitor/abnormal/ HTTP/1.0" 500 27
2018-01-10 22:42:19,131 ERROR    /usr/local/lib/python3.5/dist-packages/django/core/handlers/exception.py[line:135] Internal Server Error: /monitor/abnormal/
Traceback (most recent call last):
  File "/usr/local/lib/python3.5/dist-packages/django/core/handlers/exception.py", line 41, in inner
    response = get_response(request)
  File "/usr/local/lib/python3.5/dist-packages/django/core/handlers/base.py", line 187, in _get_response
    response = self.process_exception_by_middleware(e, request)
  File "/usr/local/lib/python3.5/dist-packages/django/core/handlers/base.py", line 185, in _get_response
    response = wrapped_callback(request, *callback_args, **callback_kwargs)
  File "/home/suyue/opsweb/monitor/views.py", line 129, in abnormal
    ac.valueCheck()
  File "/home/suyue/opsweb/utils/abNormalCheck.py", line 24, in valueCheck
    pool.apply_async(historyGet,(item,itemdata))
  File "/usr/lib/python3.5/multiprocessing/pool.py", line 322, in apply_async
    raise ValueError("Pool not running")
ValueError: Pool not running
2018-01-10 22:42:19,135 ERROR    /usr/local/lib/python3.5/dist-packages/django/core/servers/basehttp.py[line:124] "GET /monitor/abnormal/ HTTP/1.0" 500 27
2018-01-10 22:55:27,329 ERROR    /usr/local/lib/python3.5/dist-packages/django/core/handlers/exception.py[line:135] Internal Server Error: /monitor/abnormal/
Traceback (most recent call last):
  File "/usr/local/lib/python3.5/dist-packages/django/core/handlers/exception.py", line 41, in inner
    response = get_response(request)
  File "/usr/local/lib/python3.5/dist-packages/django/core/handlers/base.py", line 187, in _get_response
    response = self.process_exception_by_middleware(e, request)
  File "/usr/local/lib/python3.5/dist-packages/django/core/handlers/base.py", line 185, in _get_response
    response = wrapped_callback(request, *callback_args, **callback_kwargs)
  File "/home/suyue/opsweb/monitor/views.py", line 129, in abnormal
    ac.valueCheck()
  File "/home/suyue/opsweb/utils/abNormalCheck.py", line 22, in valueCheck
    itemdata += zabbix_data_get.item_get(parm)
  File "/home/suyue/opsweb/utils/zabbix_public_invok.py", line 33, in item_get
    result = self.__zapi.do_request("item.get", params)["result"]
AttributeError: 'str' object has no attribute 'do_request'
2018-01-10 22:55:27,359 ERROR    /usr/local/lib/python3.5/dist-packages/django/core/servers/basehttp.py[line:124] "GET /monitor/abnormal/ HTTP/1.0" 500 27
2018-01-10 22:55:29,025 ERROR    /usr/local/lib/python3.5/dist-packages/django/core/handlers/exception.py[line:135] Internal Server Error: /monitor/abnormal/
Traceback (most recent call last):
  File "/usr/local/lib/python3.5/dist-packages/django/core/handlers/exception.py", line 41, in inner
    response = get_response(request)
  File "/usr/local/lib/python3.5/dist-packages/django/core/handlers/base.py", line 187, in _get_response
    response = self.process_exception_by_middleware(e, request)
  File "/usr/local/lib/python3.5/dist-packages/django/core/handlers/base.py", line 185, in _get_response
    response = wrapped_callback(request, *callback_args, **callback_kwargs)
  File "/home/suyue/opsweb/monitor/views.py", line 129, in abnormal
    ac.valueCheck()
  File "/home/suyue/opsweb/utils/abNormalCheck.py", line 22, in valueCheck
    itemdata += zabbix_data_get.item_get(parm)
  File "/home/suyue/opsweb/utils/zabbix_public_invok.py", line 33, in item_get
    result = self.__zapi.do_request("item.get", params)["result"]
AttributeError: 'str' object has no attribute 'do_request'
2018-01-10 22:55:29,030 ERROR    /usr/local/lib/python3.5/dist-packages/django/core/servers/basehttp.py[line:124] "GET /monitor/abnormal/ HTTP/1.0" 500 27
2018-01-11 10:05:33,543 ERROR    /usr/local/lib/python3.5/dist-packages/django/core/handlers/exception.py[line:135] Internal Server Error: /monitor/abnormal/
Traceback (most recent call last):
  File "/usr/local/lib/python3.5/dist-packages/django/core/handlers/exception.py", line 41, in inner
    response = get_response(request)
  File "/usr/local/lib/python3.5/dist-packages/django/core/handlers/base.py", line 187, in _get_response
    response = self.process_exception_by_middleware(e, request)
  File "/usr/local/lib/python3.5/dist-packages/django/core/handlers/base.py", line 185, in _get_response
    response = wrapped_callback(request, *callback_args, **callback_kwargs)
  File "/root/opsweb/monitor/views.py", line 129, in abnormal
    ac.valueCheck()
  File "/root/opsweb/utils/abNormalCheck.py", line 27, in valueCheck
    historyGet(item,a)
  File "/root/opsweb/utils/abNormalCheck.py", line 35, in historyGet
    if item['hosts'][0]['status'] == "0" and (int(item['lastclock']) + 180) >= now_time:
TypeError: 'int' object is not subscriptable
2018-01-11 10:05:33,633 ERROR    /usr/local/lib/python3.5/dist-packages/django/core/servers/basehttp.py[line:124] "GET /monitor/abnormal/ HTTP/1.0" 500 27
2018-01-11 10:16:46,806 ERROR    /usr/local/lib/python3.5/dist-packages/django/core/handlers/exception.py[line:135] Internal Server Error: /monitor/abnormal/
Traceback (most recent call last):
  File "/usr/local/lib/python3.5/dist-packages/django/core/handlers/exception.py", line 41, in inner
    response = get_response(request)
  File "/usr/local/lib/python3.5/dist-packages/django/core/handlers/base.py", line 187, in _get_response
    response = self.process_exception_by_middleware(e, request)
  File "/usr/local/lib/python3.5/dist-packages/django/core/handlers/base.py", line 185, in _get_response
    response = wrapped_callback(request, *callback_args, **callback_kwargs)
  File "/root/opsweb/monitor/views.py", line 129, in abnormal
    ac.valueCheck()
  File "/root/opsweb/utils/abNormalCheck.py", line 30, in valueCheck
    historyGet(item,a)
  File "/root/opsweb/utils/abNormalCheck.py", line 35, in historyGet
    config_value = app_config.get_config_value()
TypeError: get_config_value() missing 1 required positional argument: 'self'
2018-01-11 10:16:46,871 ERROR    /usr/local/lib/python3.5/dist-packages/django/core/servers/basehttp.py[line:124] "GET /monitor/abnormal/ HTTP/1.0" 500 27
2018-01-11 10:28:16,299 ERROR    /usr/local/lib/python3.5/dist-packages/django/core/handlers/exception.py[line:135] Internal Server Error: /monitor/abnormal/
Traceback (most recent call last):
  File "/usr/local/lib/python3.5/dist-packages/django/core/handlers/exception.py", line 41, in inner
    response = get_response(request)
  File "/usr/local/lib/python3.5/dist-packages/django/core/handlers/base.py", line 187, in _get_response
    response = self.process_exception_by_middleware(e, request)
  File "/usr/local/lib/python3.5/dist-packages/django/core/handlers/base.py", line 185, in _get_response
    response = wrapped_callback(request, *callback_args, **callback_kwargs)
  File "/root/opsweb/monitor/views.py", line 128, in abnormal
    ac=abnormalCheck()
  File "/root/opsweb/utils/abNormalCheck.py", line 10, in __init__
    self.__zabbix_data_get = zabbix_data()
  File "/root/opsweb/utils/zabbix_public_invok.py", line 7, in __init__
    config_value=conf.get_config_value()
TypeError: get_config_value() takes 0 positional arguments but 1 was given
2018-01-11 10:28:16,425 ERROR    /usr/local/lib/python3.5/dist-packages/django/core/servers/basehttp.py[line:124] "GET /monitor/abnormal/ HTTP/1.0" 500 27
2018-01-11 11:13:15,911 ERROR    /usr/local/lib/python3.5/dist-packages/django/core/handlers/exception.py[line:135] Internal Server Error: /monitor/abnormal/
Traceback (most recent call last):
  File "/usr/local/lib/python3.5/dist-packages/django/core/handlers/exception.py", line 41, in inner
    response = get_response(request)
  File "/usr/local/lib/python3.5/dist-packages/django/core/handlers/base.py", line 187, in _get_response
    response = self.process_exception_by_middleware(e, request)
  File "/usr/local/lib/python3.5/dist-packages/django/core/handlers/base.py", line 185, in _get_response
    response = wrapped_callback(request, *callback_args, **callback_kwargs)
  File "/root/opsweb/monitor/views.py", line 129, in abnormal
    ac.valueCheck()
  File "/root/opsweb/utils/abNormalCheck.py", line 32, in valueCheck
    print(item2.get(5))
  File "/usr/lib/python3.5/multiprocessing/pool.py", line 604, in get
    raise TimeoutError
multiprocessing.context.TimeoutError
2018-01-11 11:13:15,928 ERROR    /usr/local/lib/python3.5/dist-packages/django/core/servers/basehttp.py[line:124] "GET /monitor/abnormal/ HTTP/1.0" 500 27
2018-01-11 11:14:42,417 ERROR    /usr/local/lib/python3.5/dist-packages/django/core/handlers/exception.py[line:135] Internal Server Error: /monitor/abnormal/
Traceback (most recent call last):
  File "/usr/local/lib/python3.5/dist-packages/django/core/handlers/exception.py", line 41, in inner
    response = get_response(request)
  File "/usr/local/lib/python3.5/dist-packages/django/core/handlers/base.py", line 187, in _get_response
    response = self.process_exception_by_middleware(e, request)
  File "/usr/local/lib/python3.5/dist-packages/django/core/handlers/base.py", line 185, in _get_response
    response = wrapped_callback(request, *callback_args, **callback_kwargs)
  File "/root/opsweb/monitor/views.py", line 129, in abnormal
    ac.valueCheck()
  File "/root/opsweb/utils/abNormalCheck.py", line 32, in valueCheck
    print(item2.get(30))
  File "/usr/lib/python3.5/multiprocessing/pool.py", line 604, in get
    raise TimeoutError
multiprocessing.context.TimeoutError
2018-01-11 11:14:42,453 ERROR    /usr/local/lib/python3.5/dist-packages/django/core/servers/basehttp.py[line:124] "GET /monitor/abnormal/ HTTP/1.0" 500 27
2018-01-11 11:16:03,919 ERROR    /usr/local/lib/python3.5/dist-packages/django/core/handlers/exception.py[line:135] Internal Server Error: /monitor/abnormal/
Traceback (most recent call last):
  File "/usr/local/lib/python3.5/dist-packages/django/core/handlers/exception.py", line 41, in inner
    response = get_response(request)
  File "/usr/local/lib/python3.5/dist-packages/django/core/handlers/base.py", line 187, in _get_response
    response = self.process_exception_by_middleware(e, request)
  File "/usr/local/lib/python3.5/dist-packages/django/core/handlers/base.py", line 185, in _get_response
    response = wrapped_callback(request, *callback_args, **callback_kwargs)
  File "/root/opsweb/monitor/views.py", line 129, in abnormal
    ac.valueCheck()
  File "/root/opsweb/utils/abNormalCheck.py", line 33, in valueCheck
    print(item2.get(30))
  File "/usr/lib/python3.5/multiprocessing/pool.py", line 604, in get
    raise TimeoutError
multiprocessing.context.TimeoutError
2018-01-11 11:16:03,938 ERROR    /usr/local/lib/python3.5/dist-packages/django/core/servers/basehttp.py[line:124] "GET /monitor/abnormal/ HTTP/1.0" 500 27
2018-01-11 12:56:30,984 ERROR    /usr/local/lib/python3.5/dist-packages/django/core/handlers/exception.py[line:135] Internal Server Error: /monitor/abnormal/
Traceback (most recent call last):
  File "/usr/lib/python3.5/urllib/request.py", line 1254, in do_open
    h.request(req.get_method(), req.selector, req.data, headers)
  File "/usr/lib/python3.5/http/client.py", line 1106, in request
    self._send_request(method, url, body, headers)
  File "/usr/lib/python3.5/http/client.py", line 1151, in _send_request
    self.endheaders(body)
  File "/usr/lib/python3.5/http/client.py", line 1102, in endheaders
    self._send_output(message_body)
  File "/usr/lib/python3.5/http/client.py", line 934, in _send_output
    self.send(msg)
  File "/usr/lib/python3.5/http/client.py", line 877, in send
    self.connect()
  File "/usr/lib/python3.5/http/client.py", line 849, in connect
    (self.host,self.port), self.timeout, self.source_address)
  File "/usr/lib/python3.5/socket.py", line 711, in create_connection
    raise err
  File "/usr/lib/python3.5/socket.py", line 702, in create_connection
    sock.connect(sa)
TimeoutError: [Errno 110] Connection timed out

During handling of the above exception, another exception occurred:

Traceback (most recent call last):
  File "/usr/local/lib/python3.5/dist-packages/django/core/handlers/exception.py", line 41, in inner
    response = get_response(request)
  File "/usr/local/lib/python3.5/dist-packages/django/core/handlers/base.py", line 187, in _get_response
    response = self.process_exception_by_middleware(e, request)
  File "/usr/local/lib/python3.5/dist-packages/django/core/handlers/base.py", line 185, in _get_response
    response = wrapped_callback(request, *callback_args, **callback_kwargs)
  File "/root/opsweb/monitor/views.py", line 129, in abnormal
    ac.valueCheck()
  File "/root/opsweb/utils/abNormalCheck.py", line 25, in valueCheck
    historyGet(item, itemdata)
  File "/root/opsweb/utils/abNormalCheck.py", line 45, in historyGet
    result = zabbix_data_get.item_history_get(history_parm)
  File "/root/opsweb/utils/zabbix_public_invok.py", line 23, in item_history_get
    result=self.__zapi.do_request("history.get",params)["result"]
  File "/usr/local/lib/python3.5/dist-packages/pyzabbix/api.py", line 236, in do_request
    res = urlopen(req)
  File "/usr/local/lib/python3.5/dist-packages/pyzabbix/api.py", line 107, in inner
    res = func(req, context=ctx)
  File "/usr/local/lib/python3.5/dist-packages/pyzabbix/api.py", line 118, in urlopen
    return urllib2.urlopen(*args, **kwargs)
  File "/usr/lib/python3.5/urllib/request.py", line 163, in urlopen
    return opener.open(url, data, timeout)
  File "/usr/lib/python3.5/urllib/request.py", line 466, in open
    response = self._open(req, data)
  File "/usr/lib/python3.5/urllib/request.py", line 484, in _open
    '_open', req)
  File "/usr/lib/python3.5/urllib/request.py", line 444, in _call_chain
    result = func(*args)
  File "/usr/lib/python3.5/urllib/request.py", line 1282, in http_open
    return self.do_open(http.client.HTTPConnection, req)
  File "/usr/lib/python3.5/urllib/request.py", line 1256, in do_open
    raise URLError(err)
urllib.error.URLError: <urlopen error [Errno 110] Connection timed out>
2018-01-11 12:56:31,078 ERROR    /usr/local/lib/python3.5/dist-packages/django/core/servers/basehttp.py[line:124] "GET /monitor/abnormal/ HTTP/1.0" 500 27
2018-01-11 14:18:19,117 ERROR    /usr/local/lib/python3.5/dist-packages/django/core/handlers/exception.py[line:135] Internal Server Error: /monitor/abnormal/
Traceback (most recent call last):
  File "/usr/local/lib/python3.5/dist-packages/django/core/handlers/exception.py", line 41, in inner
    response = get_response(request)
  File "/usr/local/lib/python3.5/dist-packages/django/core/handlers/base.py", line 187, in _get_response
    response = self.process_exception_by_middleware(e, request)
  File "/usr/local/lib/python3.5/dist-packages/django/core/handlers/base.py", line 185, in _get_response
    response = wrapped_callback(request, *callback_args, **callback_kwargs)
  File "/root/opsweb/monitor/views.py", line 129, in abnormal
    ac.valueCheck()
  File "/root/opsweb/utils/abNormalCheck.py", line 25, in valueCheck
    historyGet(item,itemdata,zabbix_data_get)
  File "/root/opsweb/utils/abNormalCheck.py", line 44, in historyGet
    result = zabbix.item_history_get(history_parm)
NameError: name 'zabbix' is not defined
2018-01-11 14:18:19,146 ERROR    /usr/local/lib/python3.5/dist-packages/django/core/servers/basehttp.py[line:124] "GET /monitor/abnormal/ HTTP/1.0" 500 27
2018-01-11 14:21:16,172 ERROR    /usr/local/lib/python3.5/dist-packages/django/core/handlers/exception.py[line:135] Internal Server Error: /monitor/abnormal/
Traceback (most recent call last):
  File "/usr/lib/python3.5/urllib/request.py", line 1254, in do_open
    h.request(req.get_method(), req.selector, req.data, headers)
  File "/usr/lib/python3.5/http/client.py", line 1106, in request
    self._send_request(method, url, body, headers)
  File "/usr/lib/python3.5/http/client.py", line 1151, in _send_request
    self.endheaders(body)
  File "/usr/lib/python3.5/http/client.py", line 1102, in endheaders
    self._send_output(message_body)
  File "/usr/lib/python3.5/http/client.py", line 934, in _send_output
    self.send(msg)
  File "/usr/lib/python3.5/http/client.py", line 877, in send
    self.connect()
  File "/usr/lib/python3.5/http/client.py", line 849, in connect
    (self.host,self.port), self.timeout, self.source_address)
  File "/usr/lib/python3.5/socket.py", line 711, in create_connection
    raise err
  File "/usr/lib/python3.5/socket.py", line 702, in create_connection
    sock.connect(sa)
TimeoutError: [Errno 110] Connection timed out

During handling of the above exception, another exception occurred:

Traceback (most recent call last):
  File "/usr/local/lib/python3.5/dist-packages/django/core/handlers/exception.py", line 41, in inner
    response = get_response(request)
  File "/usr/local/lib/python3.5/dist-packages/django/core/handlers/base.py", line 187, in _get_response
    response = self.process_exception_by_middleware(e, request)
  File "/usr/local/lib/python3.5/dist-packages/django/core/handlers/base.py", line 185, in _get_response
    response = wrapped_callback(request, *callback_args, **callback_kwargs)
  File "/root/opsweb/monitor/views.py", line 129, in abnormal
    ac.valueCheck()
  File "/root/opsweb/utils/abNormalCheck.py", line 25, in valueCheck
    historyGet(item,itemdata,zabbix_data_get)
  File "/root/opsweb/utils/abNormalCheck.py", line 44, in historyGet
    result = zabbix.item_history_get(history_parm)
  File "/root/opsweb/utils/zabbix_public_invok.py", line 23, in item_history_get
    result=self.__zapi.do_request("history.get",params)["result"]
  File "/usr/local/lib/python3.5/dist-packages/pyzabbix/api.py", line 236, in do_request
    res = urlopen(req)
  File "/usr/local/lib/python3.5/dist-packages/pyzabbix/api.py", line 107, in inner
    res = func(req, context=ctx)
  File "/usr/local/lib/python3.5/dist-packages/pyzabbix/api.py", line 118, in urlopen
    return urllib2.urlopen(*args, **kwargs)
  File "/usr/lib/python3.5/urllib/request.py", line 163, in urlopen
    return opener.open(url, data, timeout)
  File "/usr/lib/python3.5/urllib/request.py", line 466, in open
    response = self._open(req, data)
  File "/usr/lib/python3.5/urllib/request.py", line 484, in _open
    '_open', req)
  File "/usr/lib/python3.5/urllib/request.py", line 444, in _call_chain
    result = func(*args)
  File "/usr/lib/python3.5/urllib/request.py", line 1282, in http_open
    return self.do_open(http.client.HTTPConnection, req)
  File "/usr/lib/python3.5/urllib/request.py", line 1256, in do_open
    raise URLError(err)
urllib.error.URLError: <urlopen error [Errno 110] Connection timed out>
2018-01-11 14:21:16,218 ERROR    /usr/local/lib/python3.5/dist-packages/django/core/servers/basehttp.py[line:124] "GET /monitor/abnormal/ HTTP/1.0" 500 27
2018-01-11 15:39:49,087 ERROR    /usr/local/lib/python3.5/dist-packages/django/core/handlers/exception.py[line:80] The request's session was deleted before the request completed. The user may have logged out in a concurrent request, for example.
2018-01-11 15:39:49,125 WARNING  /usr/local/lib/python3.5/dist-packages/django/core/servers/basehttp.py[line:124] "GET /monitor/abnormal/ HTTP/1.0" 400 26
2018-01-11 15:40:38,622 ERROR    /usr/local/lib/python3.5/dist-packages/django/core/handlers/exception.py[line:80] The request's session was deleted before the request completed. The user may have logged out in a concurrent request, for example.
2018-01-11 15:40:38,624 WARNING  /usr/local/lib/python3.5/dist-packages/django/core/servers/basehttp.py[line:124] "GET /monitor/abnormal/ HTTP/1.0" 400 26
2018-01-11 16:52:47,239 ERROR    /usr/local/lib/python3.5/dist-packages/django/core/handlers/exception.py[line:135] Internal Server Error: /monitor/abnormal/
Traceback (most recent call last):
  File "/usr/lib/python3.5/urllib/request.py", line 1254, in do_open
    h.request(req.get_method(), req.selector, req.data, headers)
  File "/usr/lib/python3.5/http/client.py", line 1106, in request
    self._send_request(method, url, body, headers)
  File "/usr/lib/python3.5/http/client.py", line 1151, in _send_request
    self.endheaders(body)
  File "/usr/lib/python3.5/http/client.py", line 1102, in endheaders
    self._send_output(message_body)
  File "/usr/lib/python3.5/http/client.py", line 934, in _send_output
    self.send(msg)
  File "/usr/lib/python3.5/http/client.py", line 877, in send
    self.connect()
  File "/usr/lib/python3.5/http/client.py", line 849, in connect
    (self.host,self.port), self.timeout, self.source_address)
  File "/usr/lib/python3.5/socket.py", line 711, in create_connection
    raise err
  File "/usr/lib/python3.5/socket.py", line 702, in create_connection
    sock.connect(sa)
TimeoutError: [Errno 110] Connection timed out

During handling of the above exception, another exception occurred:

Traceback (most recent call last):
  File "/usr/local/lib/python3.5/dist-packages/django/core/handlers/exception.py", line 41, in inner
    response = get_response(request)
  File "/usr/local/lib/python3.5/dist-packages/django/core/handlers/base.py", line 187, in _get_response
    response = self.process_exception_by_middleware(e, request)
  File "/usr/local/lib/python3.5/dist-packages/django/core/handlers/base.py", line 185, in _get_response
    response = wrapped_callback(request, *callback_args, **callback_kwargs)
  File "/root/opsweb/monitor/views.py", line 128, in abnormal
    ac=abnormalCheck()
  File "/root/opsweb/utils/abNormalCheck.py", line 9, in __init__
    self.__zabbix_data_get = zabbix_data()
  File "/root/opsweb/utils/zabbix_public_invok.py", line 7, in __init__
    self.__zapi = ZabbixAPI(url=config_value['zabbix_api_addr'][0],user=config_value['zabbix_api_user'][0],password=config_value['zabbix_api_user'][1])
  File "/usr/local/lib/python3.5/dist-packages/pyzabbix/api.py", line 156, in __init__
    self._login(user, password)
  File "/usr/local/lib/python3.5/dist-packages/pyzabbix/api.py", line 186, in _login
    self.auth = self.user.login(user=user, password=password)
  File "/usr/local/lib/python3.5/dist-packages/pyzabbix/api.py", line 82, in fn
    args or kwargs
  File "/usr/local/lib/python3.5/dist-packages/pyzabbix/api.py", line 236, in do_request
    res = urlopen(req)
  File "/usr/local/lib/python3.5/dist-packages/pyzabbix/api.py", line 107, in inner
    res = func(req, context=ctx)
  File "/usr/local/lib/python3.5/dist-packages/pyzabbix/api.py", line 118, in urlopen
    return urllib2.urlopen(*args, **kwargs)
  File "/usr/lib/python3.5/urllib/request.py", line 163, in urlopen
    return opener.open(url, data, timeout)
  File "/usr/lib/python3.5/urllib/request.py", line 466, in open
    response = self._open(req, data)
  File "/usr/lib/python3.5/urllib/request.py", line 484, in _open
    '_open', req)
  File "/usr/lib/python3.5/urllib/request.py", line 444, in _call_chain
    result = func(*args)
  File "/usr/lib/python3.5/urllib/request.py", line 1282, in http_open
    return self.do_open(http.client.HTTPConnection, req)
  File "/usr/lib/python3.5/urllib/request.py", line 1256, in do_open
    raise URLError(err)
urllib.error.URLError: <urlopen error [Errno 110] Connection timed out>
2018-01-11 16:52:47,260 ERROR    /usr/local/lib/python3.5/dist-packages/django/core/servers/basehttp.py[line:124] "GET /monitor/abnormal/ HTTP/1.0" 500 27
2018-01-11 17:25:41,313 ERROR    /usr/local/lib/python3.5/dist-packages/django/core/handlers/exception.py[line:135] Internal Server Error: /monitor/abnormal/
Traceback (most recent call last):
  File "/usr/local/lib/python3.5/dist-packages/django/core/handlers/exception.py", line 41, in inner
    response = get_response(request)
  File "/usr/local/lib/python3.5/dist-packages/django/core/handlers/base.py", line 187, in _get_response
    response = self.process_exception_by_middleware(e, request)
  File "/usr/local/lib/python3.5/dist-packages/django/core/handlers/base.py", line 185, in _get_response
    response = wrapped_callback(request, *callback_args, **callback_kwargs)
  File "/root/opsweb/monitor/views.py", line 129, in abnormal
    ac.valueCheck()
  File "/root/opsweb/utils/abNormalCheck.py", line 14, in valueCheck
    pool = multiprocessing.dummy.Pool(20)
AttributeError: module 'multiprocessing' has no attribute 'dummy'
2018-01-11 17:25:42,195 ERROR    /usr/local/lib/python3.5/dist-packages/django/core/servers/basehttp.py[line:124] "GET /monitor/abnormal/ HTTP/1.0" 500 27
2018-01-15 19:53:19,800 ERROR    /usr/local/lib/python3.5/dist-packages/django/core/handlers/exception.py[line:135] Internal Server Error: /monitor/abnormal/
Traceback (most recent call last):
  File "/usr/lib/python3.5/urllib/request.py", line 1254, in do_open
    h.request(req.get_method(), req.selector, req.data, headers)
  File "/usr/lib/python3.5/http/client.py", line 1106, in request
    self._send_request(method, url, body, headers)
  File "/usr/lib/python3.5/http/client.py", line 1151, in _send_request
    self.endheaders(body)
  File "/usr/lib/python3.5/http/client.py", line 1102, in endheaders
    self._send_output(message_body)
  File "/usr/lib/python3.5/http/client.py", line 934, in _send_output
    self.send(msg)
  File "/usr/lib/python3.5/http/client.py", line 877, in send
    self.connect()
  File "/usr/lib/python3.5/http/client.py", line 849, in connect
    (self.host,self.port), self.timeout, self.source_address)
  File "/usr/lib/python3.5/socket.py", line 693, in create_connection
    for res in getaddrinfo(host, port, 0, SOCK_STREAM):
  File "/usr/lib/python3.5/socket.py", line 732, in getaddrinfo
    for res in _socket.getaddrinfo(host, port, family, type, proto, flags):
socket.gaierror: [Errno -3] Temporary failure in name resolution

During handling of the above exception, another exception occurred:

Traceback (most recent call last):
  File "/usr/local/lib/python3.5/dist-packages/django/core/handlers/exception.py", line 41, in inner
    response = get_response(request)
  File "/usr/local/lib/python3.5/dist-packages/django/core/handlers/base.py", line 187, in _get_response
    response = self.process_exception_by_middleware(e, request)
  File "/usr/local/lib/python3.5/dist-packages/django/core/handlers/base.py", line 185, in _get_response
    response = wrapped_callback(request, *callback_args, **callback_kwargs)
  File "/home/suyue/opsweb/monitor/views.py", line 129, in abnormal
    ac=abnormalCheck()
  File "/home/suyue/opsweb/utils/abNormalCheck.py", line 10, in __init__
    self.__zabbix_data_get = zabbix_data()
  File "/home/suyue/opsweb/utils/zabbix_public_invok.py", line 7, in __init__
    self.__zapi = ZabbixAPI(url=config_value['zabbix_api_addr'][0],user=config_value['zabbix_api_user'][0],password=config_value['zabbix_api_user'][1])
  File "/usr/local/lib/python3.5/dist-packages/pyzabbix/api.py", line 156, in __init__
    self._login(user, password)
  File "/usr/local/lib/python3.5/dist-packages/pyzabbix/api.py", line 186, in _login
    self.auth = self.user.login(user=user, password=password)
  File "/usr/local/lib/python3.5/dist-packages/pyzabbix/api.py", line 82, in fn
    args or kwargs
  File "/usr/local/lib/python3.5/dist-packages/pyzabbix/api.py", line 236, in do_request
    res = urlopen(req)
  File "/usr/local/lib/python3.5/dist-packages/pyzabbix/api.py", line 107, in inner
    res = func(req, context=ctx)
  File "/usr/local/lib/python3.5/dist-packages/pyzabbix/api.py", line 118, in urlopen
    return urllib2.urlopen(*args, **kwargs)
  File "/usr/lib/python3.5/urllib/request.py", line 163, in urlopen
    return opener.open(url, data, timeout)
  File "/usr/lib/python3.5/urllib/request.py", line 466, in open
    response = self._open(req, data)
  File "/usr/lib/python3.5/urllib/request.py", line 484, in _open
    '_open', req)
  File "/usr/lib/python3.5/urllib/request.py", line 444, in _call_chain
    result = func(*args)
  File "/usr/lib/python3.5/urllib/request.py", line 1282, in http_open
    return self.do_open(http.client.HTTPConnection, req)
  File "/usr/lib/python3.5/urllib/request.py", line 1256, in do_open
    raise URLError(err)
urllib.error.URLError: <urlopen error [Errno -3] Temporary failure in name resolution>
2018-01-15 19:53:20,001 ERROR    /usr/local/lib/python3.5/dist-packages/django/core/servers/basehttp.py[line:124] "GET /monitor/abnormal/ HTTP/1.0" 500 27
2018-01-15 19:53:37,853 ERROR    /usr/local/lib/python3.5/dist-packages/django/core/handlers/exception.py[line:135] Internal Server Error: /monitor/abnormal/
Traceback (most recent call last):
  File "/usr/lib/python3.5/urllib/request.py", line 1254, in do_open
    h.request(req.get_method(), req.selector, req.data, headers)
  File "/usr/lib/python3.5/http/client.py", line 1106, in request
    self._send_request(method, url, body, headers)
  File "/usr/lib/python3.5/http/client.py", line 1151, in _send_request
    self.endheaders(body)
  File "/usr/lib/python3.5/http/client.py", line 1102, in endheaders
    self._send_output(message_body)
  File "/usr/lib/python3.5/http/client.py", line 934, in _send_output
    self.send(msg)
  File "/usr/lib/python3.5/http/client.py", line 877, in send
    self.connect()
  File "/usr/lib/python3.5/http/client.py", line 849, in connect
    (self.host,self.port), self.timeout, self.source_address)
  File "/usr/lib/python3.5/socket.py", line 693, in create_connection
    for res in getaddrinfo(host, port, 0, SOCK_STREAM):
  File "/usr/lib/python3.5/socket.py", line 732, in getaddrinfo
    for res in _socket.getaddrinfo(host, port, family, type, proto, flags):
socket.gaierror: [Errno -3] Temporary failure in name resolution

During handling of the above exception, another exception occurred:

Traceback (most recent call last):
  File "/usr/local/lib/python3.5/dist-packages/django/core/handlers/exception.py", line 41, in inner
    response = get_response(request)
  File "/usr/local/lib/python3.5/dist-packages/django/core/handlers/base.py", line 187, in _get_response
    response = self.process_exception_by_middleware(e, request)
  File "/usr/local/lib/python3.5/dist-packages/django/core/handlers/base.py", line 185, in _get_response
    response = wrapped_callback(request, *callback_args, **callback_kwargs)
  File "/home/suyue/opsweb/monitor/views.py", line 129, in abnormal
    ac=abnormalCheck()
  File "/home/suyue/opsweb/utils/abNormalCheck.py", line 10, in __init__
    self.__zabbix_data_get = zabbix_data()
  File "/home/suyue/opsweb/utils/zabbix_public_invok.py", line 7, in __init__
    self.__zapi = ZabbixAPI(url=config_value['zabbix_api_addr'][0],user=config_value['zabbix_api_user'][0],password=config_value['zabbix_api_user'][1])
  File "/usr/local/lib/python3.5/dist-packages/pyzabbix/api.py", line 156, in __init__
    self._login(user, password)
  File "/usr/local/lib/python3.5/dist-packages/pyzabbix/api.py", line 186, in _login
    self.auth = self.user.login(user=user, password=password)
  File "/usr/local/lib/python3.5/dist-packages/pyzabbix/api.py", line 82, in fn
    args or kwargs
  File "/usr/local/lib/python3.5/dist-packages/pyzabbix/api.py", line 236, in do_request
    res = urlopen(req)
  File "/usr/local/lib/python3.5/dist-packages/pyzabbix/api.py", line 107, in inner
    res = func(req, context=ctx)
  File "/usr/local/lib/python3.5/dist-packages/pyzabbix/api.py", line 118, in urlopen
    return urllib2.urlopen(*args, **kwargs)
  File "/usr/lib/python3.5/urllib/request.py", line 163, in urlopen
    return opener.open(url, data, timeout)
  File "/usr/lib/python3.5/urllib/request.py", line 466, in open
    response = self._open(req, data)
  File "/usr/lib/python3.5/urllib/request.py", line 484, in _open
    '_open', req)
  File "/usr/lib/python3.5/urllib/request.py", line 444, in _call_chain
    result = func(*args)
  File "/usr/lib/python3.5/urllib/request.py", line 1282, in http_open
    return self.do_open(http.client.HTTPConnection, req)
  File "/usr/lib/python3.5/urllib/request.py", line 1256, in do_open
    raise URLError(err)
urllib.error.URLError: <urlopen error [Errno -3] Temporary failure in name resolution>
2018-01-15 19:53:37,855 ERROR    /usr/local/lib/python3.5/dist-packages/django/core/servers/basehttp.py[line:124] "GET /monitor/abnormal/ HTTP/1.0" 500 27
2018-01-15 19:53:55,291 ERROR    /usr/local/lib/python3.5/dist-packages/django/core/handlers/exception.py[line:135] Internal Server Error: /monitor/abnormal/
Traceback (most recent call last):
  File "/usr/lib/python3.5/urllib/request.py", line 1254, in do_open
    h.request(req.get_method(), req.selector, req.data, headers)
  File "/usr/lib/python3.5/http/client.py", line 1106, in request
    self._send_request(method, url, body, headers)
  File "/usr/lib/python3.5/http/client.py", line 1151, in _send_request
    self.endheaders(body)
  File "/usr/lib/python3.5/http/client.py", line 1102, in endheaders
    self._send_output(message_body)
  File "/usr/lib/python3.5/http/client.py", line 934, in _send_output
    self.send(msg)
  File "/usr/lib/python3.5/http/client.py", line 877, in send
    self.connect()
  File "/usr/lib/python3.5/http/client.py", line 849, in connect
    (self.host,self.port), self.timeout, self.source_address)
  File "/usr/lib/python3.5/socket.py", line 693, in create_connection
    for res in getaddrinfo(host, port, 0, SOCK_STREAM):
  File "/usr/lib/python3.5/socket.py", line 732, in getaddrinfo
    for res in _socket.getaddrinfo(host, port, family, type, proto, flags):
socket.gaierror: [Errno -3] Temporary failure in name resolution

During handling of the above exception, another exception occurred:

Traceback (most recent call last):
  File "/usr/local/lib/python3.5/dist-packages/django/core/handlers/exception.py", line 41, in inner
    response = get_response(request)
  File "/usr/local/lib/python3.5/dist-packages/django/core/handlers/base.py", line 187, in _get_response
    response = self.process_exception_by_middleware(e, request)
  File "/usr/local/lib/python3.5/dist-packages/django/core/handlers/base.py", line 185, in _get_response
    response = wrapped_callback(request, *callback_args, **callback_kwargs)
  File "/home/suyue/opsweb/monitor/views.py", line 129, in abnormal
    ac=abnormalCheck()
  File "/home/suyue/opsweb/utils/abNormalCheck.py", line 10, in __init__
    self.__zabbix_data_get = zabbix_data()
  File "/home/suyue/opsweb/utils/zabbix_public_invok.py", line 7, in __init__
    self.__zapi = ZabbixAPI(url=config_value['zabbix_api_addr'][0],user=config_value['zabbix_api_user'][0],password=config_value['zabbix_api_user'][1])
  File "/usr/local/lib/python3.5/dist-packages/pyzabbix/api.py", line 156, in __init__
    self._login(user, password)
  File "/usr/local/lib/python3.5/dist-packages/pyzabbix/api.py", line 186, in _login
    self.auth = self.user.login(user=user, password=password)
  File "/usr/local/lib/python3.5/dist-packages/pyzabbix/api.py", line 82, in fn
    args or kwargs
  File "/usr/local/lib/python3.5/dist-packages/pyzabbix/api.py", line 236, in do_request
    res = urlopen(req)
  File "/usr/local/lib/python3.5/dist-packages/pyzabbix/api.py", line 107, in inner
    res = func(req, context=ctx)
  File "/usr/local/lib/python3.5/dist-packages/pyzabbix/api.py", line 118, in urlopen
    return urllib2.urlopen(*args, **kwargs)
  File "/usr/lib/python3.5/urllib/request.py", line 163, in urlopen
    return opener.open(url, data, timeout)
  File "/usr/lib/python3.5/urllib/request.py", line 466, in open
    response = self._open(req, data)
  File "/usr/lib/python3.5/urllib/request.py", line 484, in _open
    '_open', req)
  File "/usr/lib/python3.5/urllib/request.py", line 444, in _call_chain
    result = func(*args)
  File "/usr/lib/python3.5/urllib/request.py", line 1282, in http_open
    return self.do_open(http.client.HTTPConnection, req)
  File "/usr/lib/python3.5/urllib/request.py", line 1256, in do_open
    raise URLError(err)
urllib.error.URLError: <urlopen error [Errno -3] Temporary failure in name resolution>
2018-01-15 19:53:55,293 ERROR    /usr/local/lib/python3.5/dist-packages/django/core/servers/basehttp.py[line:124] "GET /monitor/abnormal/ HTTP/1.0" 500 27
2018-01-15 19:54:09,607 ERROR    /usr/local/lib/python3.5/dist-packages/django/core/handlers/exception.py[line:135] Internal Server Error: /monitor/abnormal/
Traceback (most recent call last):
  File "/usr/local/lib/python3.5/dist-packages/django/core/handlers/exception.py", line 41, in inner
    response = get_response(request)
  File "/usr/local/lib/python3.5/dist-packages/django/core/handlers/base.py", line 187, in _get_response
    response = self.process_exception_by_middleware(e, request)
  File "/usr/local/lib/python3.5/dist-packages/django/core/handlers/base.py", line 185, in _get_response
    response = wrapped_callback(request, *callback_args, **callback_kwargs)
  File "/home/suyue/opsweb/monitor/views.py", line 131, in abnormal
    a=cpPoll(process=10)
  File "/home/suyue/opsweb/utils/customMultiprocessingPool.py", line 18, in __init__
    self.__init_pool()
  File "/home/suyue/opsweb/utils/customMultiprocessingPool.py", line 22, in __init_pool
    pro=multiprocessing.Process(self.__woekr_handle)
  File "/usr/lib/python3.5/multiprocessing/process.py", line 73, in __init__
    assert group is None, 'group argument must be None for now'
AssertionError: group argument must be None for now
2018-01-15 19:54:09,653 ERROR    /usr/local/lib/python3.5/dist-packages/django/core/servers/basehttp.py[line:124] "GET /monitor/abnormal/ HTTP/1.0" 500 27
2018-01-15 19:54:37,199 ERROR    /usr/local/lib/python3.5/dist-packages/django/core/handlers/exception.py[line:135] Internal Server Error: /monitor/abnormal/
Traceback (most recent call last):
  File "/usr/local/lib/python3.5/dist-packages/django/core/handlers/exception.py", line 41, in inner
    response = get_response(request)
  File "/usr/local/lib/python3.5/dist-packages/django/core/handlers/base.py", line 187, in _get_response
    response = self.process_exception_by_middleware(e, request)
  File "/usr/local/lib/python3.5/dist-packages/django/core/handlers/base.py", line 185, in _get_response
    response = wrapped_callback(request, *callback_args, **callback_kwargs)
  File "/home/suyue/opsweb/monitor/views.py", line 131, in abnormal
    a=cpPoll(process=10)
  File "/home/suyue/opsweb/utils/customMultiprocessingPool.py", line 18, in __init__
    self.__init_pool()
  File "/home/suyue/opsweb/utils/customMultiprocessingPool.py", line 22, in __init_pool
    pro=multiprocessing.Process(__woekr_handle)
NameError: name '_cpPoll__woekr_handle' is not defined
2018-01-15 19:54:37,217 ERROR    /usr/local/lib/python3.5/dist-packages/django/core/servers/basehttp.py[line:124] "GET /monitor/abnormal/ HTTP/1.0" 500 27
2018-01-15 20:00:19,468 ERROR    /usr/local/lib/python3.5/dist-packages/django/core/handlers/exception.py[line:135] Internal Server Error: /monitor/abnormal/
Traceback (most recent call last):
  File "/usr/local/lib/python3.5/dist-packages/django/core/handlers/exception.py", line 41, in inner
    response = get_response(request)
  File "/usr/local/lib/python3.5/dist-packages/django/core/handlers/base.py", line 187, in _get_response
    response = self.process_exception_by_middleware(e, request)
  File "/usr/local/lib/python3.5/dist-packages/django/core/handlers/base.py", line 185, in _get_response
    response = wrapped_callback(request, *callback_args, **callback_kwargs)
  File "/home/suyue/opsweb/monitor/views.py", line 131, in abnormal
    a=cpPoll(process=4)
  File "/home/suyue/opsweb/utils/customMultiprocessingPool.py", line 18, in __init__
    self.__init_pool()
  File "/home/suyue/opsweb/utils/customMultiprocessingPool.py", line 23, in __init_pool
    pro.deamon = true
NameError: name 'true' is not defined
2018-01-15 20:00:19,484 ERROR    /usr/local/lib/python3.5/dist-packages/django/core/servers/basehttp.py[line:124] "GET /monitor/abnormal/ HTTP/1.0" 500 27
2018-01-16 15:25:08,186 ERROR    /usr/local/lib/python3.5/dist-packages/django/core/handlers/exception.py[line:135] Internal Server Error: /monitor/abnormal/
Traceback (most recent call last):
  File "/usr/local/lib/python3.5/dist-packages/django/core/handlers/exception.py", line 41, in inner
    response = get_response(request)
  File "/usr/local/lib/python3.5/dist-packages/django/core/handlers/base.py", line 187, in _get_response
    response = self.process_exception_by_middleware(e, request)
  File "/usr/local/lib/python3.5/dist-packages/django/core/handlers/base.py", line 185, in _get_response
    response = wrapped_callback(request, *callback_args, **callback_kwargs)
  File "/root/opsweb/monitor/views.py", line 131, in abnormal
    a=cpPoll(process=4)
  File "/root/opsweb/utils/customMultiprocessingPool.py", line 18, in __init__
    self.__init_pool()
  File "/root/opsweb/utils/customMultiprocessingPool.py", line 24, in __init_pool
    pool_list.append(multiprocessing.Process(target=woekr_handle))
NameError: name 'woekr_handle' is not defined
2018-01-16 15:25:08,274 ERROR    /usr/local/lib/python3.5/dist-packages/django/core/servers/basehttp.py[line:124] "GET /monitor/abnormal/ HTTP/1.0" 500 27
2018-01-16 15:38:30,721 ERROR    /usr/local/lib/python3.5/dist-packages/django/core/handlers/exception.py[line:135] Internal Server Error: /monitor/abnormal/
Traceback (most recent call last):
  File "/usr/local/lib/python3.5/dist-packages/django/core/handlers/exception.py", line 41, in inner
    response = get_response(request)
  File "/usr/local/lib/python3.5/dist-packages/django/core/handlers/base.py", line 187, in _get_response
    response = self.process_exception_by_middleware(e, request)
  File "/usr/local/lib/python3.5/dist-packages/django/core/handlers/base.py", line 185, in _get_response
    response = wrapped_callback(request, *callback_args, **callback_kwargs)
  File "/root/opsweb/monitor/views.py", line 131, in abnormal
    a=cpPoll(process=4)
  File "/root/opsweb/utils/customMultiprocessingPool.py", line 15, in __init__
    self.__task_queue=queue.SimpleQueue()
AttributeError: module 'queue' has no attribute 'SimpleQueue'
2018-01-16 15:38:30,735 ERROR    /usr/local/lib/python3.5/dist-packages/django/core/servers/basehttp.py[line:124] "GET /monitor/abnormal/ HTTP/1.0" 500 27
2018-01-16 15:39:07,992 ERROR    /usr/local/lib/python3.5/dist-packages/django/core/handlers/exception.py[line:135] Internal Server Error: /monitor/abnormal/
Traceback (most recent call last):
  File "/usr/local/lib/python3.5/dist-packages/django/core/handlers/exception.py", line 41, in inner
    response = get_response(request)
  File "/usr/local/lib/python3.5/dist-packages/django/core/handlers/base.py", line 187, in _get_response
    response = self.process_exception_by_middleware(e, request)
  File "/usr/local/lib/python3.5/dist-packages/django/core/handlers/base.py", line 185, in _get_response
    response = wrapped_callback(request, *callback_args, **callback_kwargs)
  File "/root/opsweb/monitor/views.py", line 131, in abnormal
    a=cpPoll(process=4)
  File "/root/opsweb/utils/customMultiprocessingPool.py", line 15, in __init__
    self.__task_queue=queues.SimpleQueue()
TypeError: __init__() missing 1 required keyword-only argument: 'ctx'
2018-01-16 15:39:08,014 ERROR    /usr/local/lib/python3.5/dist-packages/django/core/servers/basehttp.py[line:124] "GET /monitor/abnormal/ HTTP/1.0" 500 27
2018-01-16 15:40:01,583 ERROR    /usr/local/lib/python3.5/dist-packages/django/core/handlers/exception.py[line:135] Internal Server Error: /monitor/abnormal/
Traceback (most recent call last):
  File "/usr/local/lib/python3.5/dist-packages/django/core/handlers/exception.py", line 41, in inner
    response = get_response(request)
  File "/usr/local/lib/python3.5/dist-packages/django/core/handlers/base.py", line 187, in _get_response
    response = self.process_exception_by_middleware(e, request)
  File "/usr/local/lib/python3.5/dist-packages/django/core/handlers/base.py", line 185, in _get_response
    response = wrapped_callback(request, *callback_args, **callback_kwargs)
  File "/root/opsweb/monitor/views.py", line 131, in abnormal
    a=cpPoll(process=4)
  File "/root/opsweb/utils/customMultiprocessingPool.py", line 15, in __init__
    self.__task_queue=queues.Queue()
TypeError: __init__() missing 1 required keyword-only argument: 'ctx'
2018-01-16 15:40:01,612 ERROR    /usr/local/lib/python3.5/dist-packages/django/core/servers/basehttp.py[line:124] "GET /monitor/abnormal/ HTTP/1.0" 500 27
2018-01-16 15:43:03,358 ERROR    /usr/local/lib/python3.5/dist-packages/django/core/handlers/exception.py[line:135] Internal Server Error: /monitor/abnormal/
Traceback (most recent call last):
  File "/usr/local/lib/python3.5/dist-packages/django/core/handlers/exception.py", line 41, in inner
    response = get_response(request)
  File "/usr/local/lib/python3.5/dist-packages/django/core/handlers/base.py", line 187, in _get_response
    response = self.process_exception_by_middleware(e, request)
  File "/usr/local/lib/python3.5/dist-packages/django/core/handlers/base.py", line 185, in _get_response
    response = wrapped_callback(request, *callback_args, **callback_kwargs)
  File "/root/opsweb/monitor/views.py", line 131, in abnormal
    a=cpPoll(process=4)
  File "/root/opsweb/utils/customMultiprocessingPool.py", line 15, in __init__
    self.__task_queue=Queue.Queue()
AttributeError: 'function' object has no attribute 'Queue'
2018-01-16 15:43:03,368 ERROR    /usr/local/lib/python3.5/dist-packages/django/core/servers/basehttp.py[line:124] "GET /monitor/abnormal/ HTTP/1.0" 500 27
2018-01-16 15:43:13,531 ERROR    /usr/local/lib/python3.5/dist-packages/django/core/handlers/exception.py[line:135] Internal Server Error: /monitor/abnormal/
Traceback (most recent call last):
  File "/usr/local/lib/python3.5/dist-packages/django/core/handlers/exception.py", line 41, in inner
    response = get_response(request)
  File "/usr/local/lib/python3.5/dist-packages/django/core/handlers/base.py", line 187, in _get_response
    response = self.process_exception_by_middleware(e, request)
  File "/usr/local/lib/python3.5/dist-packages/django/core/handlers/base.py", line 185, in _get_response
    response = wrapped_callback(request, *callback_args, **callback_kwargs)
  File "/root/opsweb/monitor/views.py", line 131, in abnormal
    a=cpPoll(process=4)
  File "/root/opsweb/utils/customMultiprocessingPool.py", line 18, in __init__
    self.__init_pool()
  File "/root/opsweb/utils/customMultiprocessingPool.py", line 24, in __init_pool
    pool_list.append(process(target=worker,args=(i,)))
TypeError: 'module' object is not callable
2018-01-16 15:43:13,566 ERROR    /usr/local/lib/python3.5/dist-packages/django/core/servers/basehttp.py[line:124] "GET /monitor/abnormal/ HTTP/1.0" 500 27
2018-01-16 15:43:44,372 ERROR    /usr/local/lib/python3.5/dist-packages/django/core/handlers/exception.py[line:135] Internal Server Error: /monitor/abnormal/
Traceback (most recent call last):
  File "/usr/local/lib/python3.5/dist-packages/django/core/handlers/exception.py", line 41, in inner
    response = get_response(request)
  File "/usr/local/lib/python3.5/dist-packages/django/core/handlers/base.py", line 187, in _get_response
    response = self.process_exception_by_middleware(e, request)
  File "/usr/local/lib/python3.5/dist-packages/django/core/handlers/base.py", line 185, in _get_response
    response = wrapped_callback(request, *callback_args, **callback_kwargs)
  File "/root/opsweb/monitor/views.py", line 131, in abnormal
    a=cpPoll(process=4)
  File "/root/opsweb/utils/customMultiprocessingPool.py", line 18, in __init__
    self.__init_pool()
  File "/root/opsweb/utils/customMultiprocessingPool.py", line 24, in __init_pool
    pool_list.append(process(target=worker,args=(i,)))
TypeError: 'module' object is not callable
2018-01-16 15:43:44,385 ERROR    /usr/local/lib/python3.5/dist-packages/django/core/servers/basehttp.py[line:124] "GET /monitor/abnormal/ HTTP/1.0" 500 27
2018-01-16 15:44:21,082 ERROR    /usr/local/lib/python3.5/dist-packages/django/core/handlers/exception.py[line:135] Internal Server Error: /monitor/abnormal/
Traceback (most recent call last):
  File "/usr/local/lib/python3.5/dist-packages/django/core/handlers/exception.py", line 41, in inner
    response = get_response(request)
  File "/usr/local/lib/python3.5/dist-packages/django/core/handlers/base.py", line 187, in _get_response
    response = self.process_exception_by_middleware(e, request)
  File "/usr/local/lib/python3.5/dist-packages/django/core/handlers/base.py", line 185, in _get_response
    response = wrapped_callback(request, *callback_args, **callback_kwargs)
  File "/root/opsweb/monitor/views.py", line 131, in abnormal
    a=cpPoll(process=4)
  File "/root/opsweb/utils/customMultiprocessingPool.py", line 18, in __init__
    self.__init_pool()
  File "/root/opsweb/utils/customMultiprocessingPool.py", line 24, in __init_pool
    pool_list.append(process(target=worker))
TypeError: 'module' object is not callable
2018-01-16 15:44:21,095 ERROR    /usr/local/lib/python3.5/dist-packages/django/core/servers/basehttp.py[line:124] "GET /monitor/abnormal/ HTTP/1.0" 500 27
2018-01-16 15:44:49,280 ERROR    /usr/local/lib/python3.5/dist-packages/django/core/handlers/exception.py[line:135] Internal Server Error: /monitor/abnormal/
Traceback (most recent call last):
  File "/usr/local/lib/python3.5/dist-packages/django/core/handlers/exception.py", line 41, in inner
    response = get_response(request)
  File "/usr/local/lib/python3.5/dist-packages/django/core/handlers/base.py", line 187, in _get_response
    response = self.process_exception_by_middleware(e, request)
  File "/usr/local/lib/python3.5/dist-packages/django/core/handlers/base.py", line 185, in _get_response
    response = wrapped_callback(request, *callback_args, **callback_kwargs)
  File "/root/opsweb/monitor/views.py", line 131, in abnormal
    a=cpPoll(process=4)
  File "/root/opsweb/utils/customMultiprocessingPool.py", line 18, in __init__
    self.__init_pool()
  File "/root/opsweb/utils/customMultiprocessingPool.py", line 24, in __init_pool
    pool_list.append(process(target=worker,args=(3,)))
TypeError: 'module' object is not callable
2018-01-16 15:44:49,294 ERROR    /usr/local/lib/python3.5/dist-packages/django/core/servers/basehttp.py[line:124] "GET /monitor/abnormal/ HTTP/1.0" 500 27
2018-01-16 15:45:21,481 ERROR    /usr/local/lib/python3.5/dist-packages/django/core/handlers/exception.py[line:135] Internal Server Error: /monitor/abnormal/
Traceback (most recent call last):
  File "/usr/local/lib/python3.5/dist-packages/django/core/handlers/exception.py", line 41, in inner
    response = get_response(request)
  File "/usr/local/lib/python3.5/dist-packages/django/core/handlers/base.py", line 187, in _get_response
    response = self.process_exception_by_middleware(e, request)
  File "/usr/local/lib/python3.5/dist-packages/django/core/handlers/base.py", line 185, in _get_response
    response = wrapped_callback(request, *callback_args, **callback_kwargs)
  File "/root/opsweb/monitor/views.py", line 131, in abnormal
    a=cpPoll(process=4)
  File "/root/opsweb/utils/customMultiprocessingPool.py", line 18, in __init__
    self.__init_pool()
  File "/root/opsweb/utils/customMultiprocessingPool.py", line 24, in __init_pool
    pool_list.append(process(target=tttt,args=(3,)))
TypeError: 'module' object is not callable
2018-01-16 15:45:21,497 ERROR    /usr/local/lib/python3.5/dist-packages/django/core/servers/basehttp.py[line:124] "GET /monitor/abnormal/ HTTP/1.0" 500 27
2018-01-16 15:45:52,469 ERROR    /usr/local/lib/python3.5/dist-packages/django/core/handlers/exception.py[line:135] Internal Server Error: /monitor/abnormal/
Traceback (most recent call last):
  File "/usr/local/lib/python3.5/dist-packages/django/core/handlers/exception.py", line 41, in inner
    response = get_response(request)
  File "/usr/local/lib/python3.5/dist-packages/django/core/handlers/base.py", line 187, in _get_response
    response = self.process_exception_by_middleware(e, request)
  File "/usr/local/lib/python3.5/dist-packages/django/core/handlers/base.py", line 185, in _get_response
    response = wrapped_callback(request, *callback_args, **callback_kwargs)
  File "/root/opsweb/monitor/views.py", line 131, in abnormal
    a=cpPoll(process=4)
  File "/root/opsweb/utils/customMultiprocessingPool.py", line 17, in __init__
    self.__init_pool()
  File "/root/opsweb/utils/customMultiprocessingPool.py", line 23, in __init_pool
    pool_list.append(process(target=worker,args=(3,)))
TypeError: 'module' object is not callable
2018-01-16 15:45:52,489 ERROR    /usr/local/lib/python3.5/dist-packages/django/core/servers/basehttp.py[line:124] "GET /monitor/abnormal/ HTTP/1.0" 500 27
2018-01-16 16:48:17,160 ERROR    /usr/local/lib/python3.5/dist-packages/django/core/handlers/exception.py[line:135] Internal Server Error: /monitor/abnormal/
Traceback (most recent call last):
  File "/usr/local/lib/python3.5/dist-packages/django/core/handlers/exception.py", line 41, in inner
    response = get_response(request)
  File "/usr/local/lib/python3.5/dist-packages/django/core/handlers/base.py", line 187, in _get_response
    response = self.process_exception_by_middleware(e, request)
  File "/usr/local/lib/python3.5/dist-packages/django/core/handlers/base.py", line 185, in _get_response
    response = wrapped_callback(request, *callback_args, **callback_kwargs)
  File "/root/opsweb/monitor/views.py", line 132, in abnormal
    for i in (10000):
TypeError: 'int' object is not iterable
2018-01-16 16:48:17,206 ERROR    /usr/local/lib/python3.5/dist-packages/django/core/servers/basehttp.py[line:124] "GET /monitor/abnormal/ HTTP/1.0" 500 27
2018-01-16 16:48:47,787 ERROR    /usr/local/lib/python3.5/dist-packages/django/core/handlers/exception.py[line:135] Internal Server Error: /monitor/abnormal/
Traceback (most recent call last):
  File "/usr/local/lib/python3.5/dist-packages/django/core/handlers/exception.py", line 41, in inner
    response = get_response(request)
  File "/usr/local/lib/python3.5/dist-packages/django/core/handlers/base.py", line 187, in _get_response
    response = self.process_exception_by_middleware(e, request)
  File "/usr/local/lib/python3.5/dist-packages/django/core/handlers/base.py", line 185, in _get_response
    response = wrapped_callback(request, *callback_args, **callback_kwargs)
  File "/root/opsweb/monitor/views.py", line 134, in abnormal
    a.add_task(i)
  File "/root/opsweb/utils/customMultiprocessingPool.py", line 29, in add_task
    raise ValueError("进程池已关闭，不能再添加任务")
ValueError: 进程池已关闭，不能再添加任务
2018-01-16 16:48:47,853 ERROR    /usr/local/lib/python3.5/dist-packages/django/core/servers/basehttp.py[line:124] "GET /monitor/abnormal/ HTTP/1.0" 500 27
2018-01-16 16:49:19,163 ERROR    /usr/local/lib/python3.5/dist-packages/django/core/handlers/exception.py[line:135] Internal Server Error: /monitor/abnormal/
Traceback (most recent call last):
  File "/usr/local/lib/python3.5/dist-packages/django/core/handlers/exception.py", line 41, in inner
    response = get_response(request)
  File "/usr/local/lib/python3.5/dist-packages/django/core/handlers/base.py", line 187, in _get_response
    response = self.process_exception_by_middleware(e, request)
  File "/usr/local/lib/python3.5/dist-packages/django/core/handlers/base.py", line 185, in _get_response
    response = wrapped_callback(request, *callback_args, **callback_kwargs)
  File "/root/opsweb/monitor/views.py", line 134, in abnormal
    a.pool_join()
  File "/root/opsweb/utils/customMultiprocessingPool.py", line 44, in pool_join
    raise ValueError("进程池未关闭,不能阻塞退出")
ValueError: 进程池未关闭,不能阻塞退出
2018-01-16 16:49:19,207 ERROR    /usr/local/lib/python3.5/dist-packages/django/core/servers/basehttp.py[line:124] "GET /monitor/abnormal/ HTTP/1.0" 500 27
2018-01-16 17:25:59,194 ERROR    /usr/local/lib/python3.5/dist-packages/django/core/handlers/exception.py[line:135] Internal Server Error: /monitor/abnormal/
Traceback (most recent call last):
  File "/usr/local/lib/python3.5/dist-packages/django/core/handlers/exception.py", line 41, in inner
    response = get_response(request)
  File "/usr/local/lib/python3.5/dist-packages/django/core/handlers/base.py", line 187, in _get_response
    response = self.process_exception_by_middleware(e, request)
  File "/usr/local/lib/python3.5/dist-packages/django/core/handlers/base.py", line 185, in _get_response
    response = wrapped_callback(request, *callback_args, **callback_kwargs)
  File "/root/opsweb/monitor/views.py", line 135, in abnormal
    a.pool_join()
  File "/root/opsweb/utils/customMultiprocessingPool.py", line 36, in pool_join
    self.__init_pool.join()
AttributeError: 'function' object has no attribute 'join'
2018-01-16 17:25:59,251 ERROR    /usr/local/lib/python3.5/dist-packages/django/core/servers/basehttp.py[line:124] "GET /monitor/abnormal/ HTTP/1.0" 500 27
2018-01-17 15:27:59,413 ERROR    /usr/local/lib/python3.5/dist-packages/django/core/handlers/exception.py[line:135] Internal Server Error: /monitor/abnormal/
Traceback (most recent call last):
  File "/usr/local/lib/python3.5/dist-packages/django/core/handlers/exception.py", line 41, in inner
    response = get_response(request)
  File "/usr/local/lib/python3.5/dist-packages/django/core/handlers/base.py", line 187, in _get_response
    response = self.process_exception_by_middleware(e, request)
  File "/usr/local/lib/python3.5/dist-packages/django/core/handlers/base.py", line 185, in _get_response
    response = wrapped_callback(request, *callback_args, **callback_kwargs)
  File "/root/opsweb/monitor/views.py", line 133, in abnormal
    a.add_task(i)
TypeError: add_task() missing 1 required positional argument: 'args'
2018-01-17 15:28:01,493 ERROR    /usr/local/lib/python3.5/dist-packages/django/core/servers/basehttp.py[line:124] "GET /monitor/abnormal/ HTTP/1.0" 500 27
2018-01-17 15:29:04,742 ERROR    /usr/local/lib/python3.5/dist-packages/django/core/handlers/exception.py[line:135] Internal Server Error: /monitor/abnormal/
Traceback (most recent call last):
  File "/usr/local/lib/python3.5/dist-packages/django/core/handlers/exception.py", line 41, in inner
    response = get_response(request)
  File "/usr/local/lib/python3.5/dist-packages/django/core/handlers/base.py", line 187, in _get_response
    response = self.process_exception_by_middleware(e, request)
  File "/usr/local/lib/python3.5/dist-packages/django/core/handlers/base.py", line 185, in _get_response
    response = wrapped_callback(request, *callback_args, **callback_kwargs)
  File "/root/opsweb/monitor/views.py", line 133, in abnormal
    a.add_task(i)
TypeError: add_task() missing 1 required positional argument: 'args'
2018-01-17 15:29:04,960 ERROR    /usr/local/lib/python3.5/dist-packages/django/core/servers/basehttp.py[line:124] "GET /monitor/abnormal/ HTTP/1.0" 500 27
2018-01-17 15:29:49,881 ERROR    /usr/local/lib/python3.5/dist-packages/django/core/handlers/exception.py[line:135] Internal Server Error: /monitor/abnormal/
Traceback (most recent call last):
  File "/usr/local/lib/python3.5/dist-packages/django/core/handlers/exception.py", line 41, in inner
    response = get_response(request)
  File "/usr/local/lib/python3.5/dist-packages/django/core/handlers/base.py", line 187, in _get_response
    response = self.process_exception_by_middleware(e, request)
  File "/usr/local/lib/python3.5/dist-packages/django/core/handlers/base.py", line 185, in _get_response
    response = wrapped_callback(request, *callback_args, **callback_kwargs)
  File "/root/opsweb/monitor/views.py", line 133, in abnormal
    a.add_task(target=custest,args=(i,))
TypeError: add_task() got an unexpected keyword argument 'target'
2018-01-17 15:29:50,088 ERROR    /usr/local/lib/python3.5/dist-packages/django/core/servers/basehttp.py[line:124] "GET /monitor/abnormal/ HTTP/1.0" 500 27
2018-01-17 16:21:21,835 ERROR    /usr/local/lib/python3.5/dist-packages/django/core/handlers/exception.py[line:135] Internal Server Error: /monitor/abnormal/
Traceback (most recent call last):
  File "/usr/lib/python3.5/urllib/request.py", line 1254, in do_open
    h.request(req.get_method(), req.selector, req.data, headers)
  File "/usr/lib/python3.5/http/client.py", line 1106, in request
    self._send_request(method, url, body, headers)
  File "/usr/lib/python3.5/http/client.py", line 1151, in _send_request
    self.endheaders(body)
  File "/usr/lib/python3.5/http/client.py", line 1102, in endheaders
    self._send_output(message_body)
  File "/usr/lib/python3.5/http/client.py", line 934, in _send_output
    self.send(msg)
  File "/usr/lib/python3.5/http/client.py", line 877, in send
    self.connect()
  File "/usr/lib/python3.5/http/client.py", line 849, in connect
    (self.host,self.port), self.timeout, self.source_address)
  File "/usr/lib/python3.5/socket.py", line 711, in create_connection
    raise err
  File "/usr/lib/python3.5/socket.py", line 702, in create_connection
    sock.connect(sa)
TimeoutError: [Errno 110] Connection timed out

During handling of the above exception, another exception occurred:

Traceback (most recent call last):
  File "/usr/local/lib/python3.5/dist-packages/django/core/handlers/exception.py", line 41, in inner
    response = get_response(request)
  File "/usr/local/lib/python3.5/dist-packages/django/core/handlers/base.py", line 187, in _get_response
    response = self.process_exception_by_middleware(e, request)
  File "/usr/local/lib/python3.5/dist-packages/django/core/handlers/base.py", line 185, in _get_response
    response = wrapped_callback(request, *callback_args, **callback_kwargs)
  File "/root/opsweb/monitor/views.py", line 130, in abnormal
    ac.valueCheck()
  File "/root/opsweb/utils/abNormalCheck.py", line 21, in valueCheck
    zabbix_data_get = zabbix_data()
  File "/root/opsweb/utils/zabbix_public_invok.py", line 7, in __init__
    self.__zapi = ZabbixAPI(url=config_value['zabbix_api_addr'][0],user=config_value['zabbix_api_user'][0],password=config_value['zabbix_api_user'][1])
  File "/usr/local/lib/python3.5/dist-packages/pyzabbix/api.py", line 156, in __init__
    self._login(user, password)
  File "/usr/local/lib/python3.5/dist-packages/pyzabbix/api.py", line 186, in _login
    self.auth = self.user.login(user=user, password=password)
  File "/usr/local/lib/python3.5/dist-packages/pyzabbix/api.py", line 82, in fn
    args or kwargs
  File "/usr/local/lib/python3.5/dist-packages/pyzabbix/api.py", line 236, in do_request
    res = urlopen(req)
  File "/usr/local/lib/python3.5/dist-packages/pyzabbix/api.py", line 107, in inner
    res = func(req, context=ctx)
  File "/usr/local/lib/python3.5/dist-packages/pyzabbix/api.py", line 118, in urlopen
    return urllib2.urlopen(*args, **kwargs)
  File "/usr/lib/python3.5/urllib/request.py", line 163, in urlopen
    return opener.open(url, data, timeout)
  File "/usr/lib/python3.5/urllib/request.py", line 466, in open
    response = self._open(req, data)
  File "/usr/lib/python3.5/urllib/request.py", line 484, in _open
    '_open', req)
  File "/usr/lib/python3.5/urllib/request.py", line 444, in _call_chain
    result = func(*args)
  File "/usr/lib/python3.5/urllib/request.py", line 1282, in http_open
    return self.do_open(http.client.HTTPConnection, req)
  File "/usr/lib/python3.5/urllib/request.py", line 1256, in do_open
    raise URLError(err)
urllib.error.URLError: <urlopen error [Errno 110] Connection timed out>
2018-01-17 16:21:21,927 ERROR    /usr/local/lib/python3.5/dist-packages/django/core/servers/basehttp.py[line:124] "GET /monitor/abnormal/ HTTP/1.0" 500 27
2018-01-17 16:33:01,911 ERROR    /usr/local/lib/python3.5/dist-packages/django/core/handlers/exception.py[line:135] Internal Server Error: /monitor/abnormal/
Traceback (most recent call last):
  File "/usr/local/lib/python3.5/dist-packages/django/core/handlers/exception.py", line 41, in inner
    response = get_response(request)
  File "/usr/local/lib/python3.5/dist-packages/django/core/handlers/base.py", line 187, in _get_response
    response = self.process_exception_by_middleware(e, request)
  File "/usr/local/lib/python3.5/dist-packages/django/core/handlers/base.py", line 185, in _get_response
    response = wrapped_callback(request, *callback_args, **callback_kwargs)
  File "/root/opsweb/monitor/views.py", line 129, in abnormal
    ac=abnormalCheck()
  File "/root/opsweb/utils/abNormalCheck.py", line 9, in __init__
    self.__zabbix_data_get = zabbix_data()
  File "/root/opsweb/utils/zabbix_public_invok.py", line 7, in __init__
    self.__zapi = ZabbixAPI(timeout=10,url=config_value['zabbix_api_addr'][0],user=config_value['zabbix_api_user'][0],password=config_value['zabbix_api_user'][1])
TypeError: __init__() got an unexpected keyword argument 'timeout'
2018-01-17 16:33:01,926 ERROR    /usr/local/lib/python3.5/dist-packages/django/core/servers/basehttp.py[line:124] "GET /monitor/abnormal/ HTTP/1.0" 500 27
2018-01-17 16:53:26,953 ERROR    /usr/local/lib/python3.5/dist-packages/django/core/handlers/exception.py[line:135] Internal Server Error: /monitor/abnormal/
Traceback (most recent call last):
  File "/usr/lib/python3.5/urllib/request.py", line 1254, in do_open
    h.request(req.get_method(), req.selector, req.data, headers)
  File "/usr/lib/python3.5/http/client.py", line 1106, in request
    self._send_request(method, url, body, headers)
  File "/usr/lib/python3.5/http/client.py", line 1151, in _send_request
    self.endheaders(body)
  File "/usr/lib/python3.5/http/client.py", line 1102, in endheaders
    self._send_output(message_body)
  File "/usr/lib/python3.5/http/client.py", line 934, in _send_output
    self.send(msg)
  File "/usr/lib/python3.5/http/client.py", line 877, in send
    self.connect()
  File "/usr/lib/python3.5/http/client.py", line 849, in connect
    (self.host,self.port), self.timeout, self.source_address)
  File "/usr/lib/python3.5/socket.py", line 711, in create_connection
    raise err
  File "/usr/lib/python3.5/socket.py", line 702, in create_connection
    sock.connect(sa)
TimeoutError: [Errno 110] Connection timed out

During handling of the above exception, another exception occurred:

Traceback (most recent call last):
  File "/usr/local/lib/python3.5/dist-packages/django/core/handlers/exception.py", line 41, in inner
    response = get_response(request)
  File "/usr/local/lib/python3.5/dist-packages/django/core/handlers/base.py", line 187, in _get_response
    response = self.process_exception_by_middleware(e, request)
  File "/usr/local/lib/python3.5/dist-packages/django/core/handlers/base.py", line 185, in _get_response
    response = wrapped_callback(request, *callback_args, **callback_kwargs)
  File "/root/opsweb/monitor/views.py", line 129, in abnormal
    ac=abnormalCheck()
  File "/root/opsweb/utils/abNormalCheck.py", line 9, in __init__
    self.__zabbix_data_get = zabbix_data()
  File "/root/opsweb/utils/zabbix_public_invok.py", line 7, in __init__
    self.__zapi = ZabbixAPI(url=config_value['zabbix_api_addr'][0],user=config_value['zabbix_api_user'][0],password=config_value['zabbix_api_user'][1])
  File "/usr/local/lib/python3.5/dist-packages/pyzabbix/api.py", line 156, in __init__
    self._login(user, password)
  File "/usr/local/lib/python3.5/dist-packages/pyzabbix/api.py", line 186, in _login
    self.auth = self.user.login(user=user, password=password)
  File "/usr/local/lib/python3.5/dist-packages/pyzabbix/api.py", line 82, in fn
    args or kwargs
  File "/usr/local/lib/python3.5/dist-packages/pyzabbix/api.py", line 236, in do_request
    res = urlopen(req)
  File "/usr/local/lib/python3.5/dist-packages/pyzabbix/api.py", line 107, in inner
    res = func(req, context=ctx)
  File "/usr/local/lib/python3.5/dist-packages/pyzabbix/api.py", line 118, in urlopen
    return urllib2.urlopen(*args, **kwargs)
  File "/usr/lib/python3.5/urllib/request.py", line 163, in urlopen
    return opener.open(url, data, timeout)
  File "/usr/lib/python3.5/urllib/request.py", line 466, in open
    response = self._open(req, data)
  File "/usr/lib/python3.5/urllib/request.py", line 484, in _open
    '_open', req)
  File "/usr/lib/python3.5/urllib/request.py", line 444, in _call_chain
    result = func(*args)
  File "/usr/lib/python3.5/urllib/request.py", line 1282, in http_open
    return self.do_open(http.client.HTTPConnection, req)
  File "/usr/lib/python3.5/urllib/request.py", line 1256, in do_open
    raise URLError(err)
urllib.error.URLError: <urlopen error [Errno 110] Connection timed out>
2018-01-17 16:53:26,962 ERROR    /usr/local/lib/python3.5/dist-packages/django/core/servers/basehttp.py[line:124] "GET /monitor/abnormal/ HTTP/1.0" 500 27
2018-01-17 17:33:14,921 ERROR    /usr/local/lib/python3.5/dist-packages/django/core/handlers/exception.py[line:135] Internal Server Error: /monitor/abnormal/
Traceback (most recent call last):
  File "/usr/lib/python3.5/urllib/request.py", line 1254, in do_open
    h.request(req.get_method(), req.selector, req.data, headers)
  File "/usr/lib/python3.5/http/client.py", line 1106, in request
    self._send_request(method, url, body, headers)
  File "/usr/lib/python3.5/http/client.py", line 1151, in _send_request
    self.endheaders(body)
  File "/usr/lib/python3.5/http/client.py", line 1102, in endheaders
    self._send_output(message_body)
  File "/usr/lib/python3.5/http/client.py", line 934, in _send_output
    self.send(msg)
  File "/usr/lib/python3.5/http/client.py", line 877, in send
    self.connect()
  File "/usr/lib/python3.5/http/client.py", line 849, in connect
    (self.host,self.port), self.timeout, self.source_address)
  File "/usr/lib/python3.5/socket.py", line 711, in create_connection
    raise err
  File "/usr/lib/python3.5/socket.py", line 702, in create_connection
    sock.connect(sa)
TimeoutError: [Errno 110] Connection timed out

During handling of the above exception, another exception occurred:

Traceback (most recent call last):
  File "/usr/local/lib/python3.5/dist-packages/django/core/handlers/exception.py", line 41, in inner
    response = get_response(request)
  File "/usr/local/lib/python3.5/dist-packages/django/core/handlers/base.py", line 187, in _get_response
    response = self.process_exception_by_middleware(e, request)
  File "/usr/local/lib/python3.5/dist-packages/django/core/handlers/base.py", line 185, in _get_response
    response = wrapped_callback(request, *callback_args, **callback_kwargs)
  File "/root/opsweb/monitor/views.py", line 130, in abnormal
    ac.valueCheck()
  File "/root/opsweb/utils/abNormalCheck.py", line 22, in valueCheck
    itemdata += zabbix_data_get.item_get(parm)
  File "/root/opsweb/utils/zabbix_public_invok.py", line 32, in item_get
    result = self.__zapi.do_request("item.get", params)["result"]
  File "/usr/local/lib/python3.5/dist-packages/pyzabbix/api.py", line 236, in do_request
    res = urlopen(req)
  File "/usr/local/lib/python3.5/dist-packages/pyzabbix/api.py", line 107, in inner
    res = func(req, context=ctx)
  File "/usr/local/lib/python3.5/dist-packages/pyzabbix/api.py", line 118, in urlopen
    return urllib2.urlopen(*args, **kwargs)
  File "/usr/lib/python3.5/urllib/request.py", line 163, in urlopen
    return opener.open(url, data, timeout)
  File "/usr/lib/python3.5/urllib/request.py", line 466, in open
    response = self._open(req, data)
  File "/usr/lib/python3.5/urllib/request.py", line 484, in _open
    '_open', req)
  File "/usr/lib/python3.5/urllib/request.py", line 444, in _call_chain
    result = func(*args)
  File "/usr/lib/python3.5/urllib/request.py", line 1282, in http_open
    return self.do_open(http.client.HTTPConnection, req)
  File "/usr/lib/python3.5/urllib/request.py", line 1256, in do_open
    raise URLError(err)
urllib.error.URLError: <urlopen error [Errno 110] Connection timed out>
2018-01-17 17:33:14,929 ERROR    /usr/local/lib/python3.5/dist-packages/django/core/servers/basehttp.py[line:124] "GET /monitor/abnormal/ HTTP/1.0" 500 27
2018-01-17 19:49:04,242 ERROR    /usr/local/lib/python3.5/dist-packages/django/core/handlers/exception.py[line:135] Internal Server Error: /monitor/abnormal/
Traceback (most recent call last):
  File "/usr/lib/python3.5/urllib/request.py", line 1254, in do_open
    h.request(req.get_method(), req.selector, req.data, headers)
  File "/usr/lib/python3.5/http/client.py", line 1106, in request
    self._send_request(method, url, body, headers)
  File "/usr/lib/python3.5/http/client.py", line 1151, in _send_request
    self.endheaders(body)
  File "/usr/lib/python3.5/http/client.py", line 1102, in endheaders
    self._send_output(message_body)
  File "/usr/lib/python3.5/http/client.py", line 934, in _send_output
    self.send(msg)
  File "/usr/lib/python3.5/http/client.py", line 877, in send
    self.connect()
  File "/usr/lib/python3.5/http/client.py", line 849, in connect
    (self.host,self.port), self.timeout, self.source_address)
  File "/usr/lib/python3.5/socket.py", line 693, in create_connection
    for res in getaddrinfo(host, port, 0, SOCK_STREAM):
  File "/usr/lib/python3.5/socket.py", line 732, in getaddrinfo
    for res in _socket.getaddrinfo(host, port, family, type, proto, flags):
socket.gaierror: [Errno -3] Temporary failure in name resolution

During handling of the above exception, another exception occurred:

Traceback (most recent call last):
  File "/usr/local/lib/python3.5/dist-packages/django/core/handlers/exception.py", line 41, in inner
    response = get_response(request)
  File "/usr/local/lib/python3.5/dist-packages/django/core/handlers/base.py", line 187, in _get_response
    response = self.process_exception_by_middleware(e, request)
  File "/usr/local/lib/python3.5/dist-packages/django/core/handlers/base.py", line 185, in _get_response
    response = wrapped_callback(request, *callback_args, **callback_kwargs)
  File "/home/suyue/opsweb/monitor/views.py", line 129, in abnormal
    ac=abnormalCheck()
  File "/home/suyue/opsweb/utils/abNormalCheck.py", line 9, in __init__
    self.__zabbix_data_get = zabbix_data()
  File "/home/suyue/opsweb/utils/zabbix_public_invok.py", line 7, in __init__
    self.__zapi = ZabbixAPI(url=config_value['zabbix_api_addr'][0],user=config_value['zabbix_api_user'][0],password=config_value['zabbix_api_user'][1])
  File "/usr/local/lib/python3.5/dist-packages/pyzabbix/api.py", line 156, in __init__
    self._login(user, password)
  File "/usr/local/lib/python3.5/dist-packages/pyzabbix/api.py", line 186, in _login
    self.auth = self.user.login(user=user, password=password)
  File "/usr/local/lib/python3.5/dist-packages/pyzabbix/api.py", line 82, in fn
    args or kwargs
  File "/usr/local/lib/python3.5/dist-packages/pyzabbix/api.py", line 236, in do_request
    res = urlopen(req)
  File "/usr/local/lib/python3.5/dist-packages/pyzabbix/api.py", line 107, in inner
    res = func(req, context=ctx)
  File "/usr/local/lib/python3.5/dist-packages/pyzabbix/api.py", line 118, in urlopen
    return urllib2.urlopen(*args, **kwargs)
  File "/usr/lib/python3.5/urllib/request.py", line 163, in urlopen
    return opener.open(url, data, timeout)
  File "/usr/lib/python3.5/urllib/request.py", line 466, in open
    response = self._open(req, data)
  File "/usr/lib/python3.5/urllib/request.py", line 484, in _open
    '_open', req)
  File "/usr/lib/python3.5/urllib/request.py", line 444, in _call_chain
    result = func(*args)
  File "/usr/lib/python3.5/urllib/request.py", line 1282, in http_open
    return self.do_open(http.client.HTTPConnection, req)
  File "/usr/lib/python3.5/urllib/request.py", line 1256, in do_open
    raise URLError(err)
urllib.error.URLError: <urlopen error [Errno -3] Temporary failure in name resolution>
2018-01-17 19:49:04,638 ERROR    /usr/local/lib/python3.5/dist-packages/django/core/servers/basehttp.py[line:124] "GET /monitor/abnormal/ HTTP/1.0" 500 27
2018-01-17 19:55:23,451 ERROR    /usr/local/lib/python3.5/dist-packages/django/core/handlers/exception.py[line:135] Internal Server Error: /monitor/abnormal/
Traceback (most recent call last):
  File "/usr/local/lib/python3.5/dist-packages/django/core/handlers/exception.py", line 41, in inner
    response = get_response(request)
  File "/usr/local/lib/python3.5/dist-packages/django/core/handlers/base.py", line 187, in _get_response
    response = self.process_exception_by_middleware(e, request)
  File "/usr/local/lib/python3.5/dist-packages/django/core/handlers/base.py", line 185, in _get_response
    response = wrapped_callback(request, *callback_args, **callback_kwargs)
  File "/home/suyue/opsweb/monitor/views.py", line 130, in abnormal
    ac.valueCheck()
  File "/home/suyue/opsweb/utils/abNormalCheck.py", line 30, in valueCheck
    result=a.get_task()
  File "/home/suyue/opsweb/utils/customMultiprocessingPool.py", line 45, in get_task
    elif not self.__pool_state and self.__pool_state.empty():
AttributeError: 'bool' object has no attribute 'empty'
2018-01-17 19:55:23,475 ERROR    /usr/local/lib/python3.5/dist-packages/django/core/servers/basehttp.py[line:124] "GET /monitor/abnormal/ HTTP/1.0" 500 27
2018-01-17 19:57:37,331 ERROR    /usr/local/lib/python3.5/dist-packages/django/core/handlers/exception.py[line:135] Internal Server Error: /monitor/abnormal/
Traceback (most recent call last):
  File "/usr/local/lib/python3.5/dist-packages/django/core/handlers/exception.py", line 41, in inner
    response = get_response(request)
  File "/usr/local/lib/python3.5/dist-packages/django/core/handlers/base.py", line 187, in _get_response
    response = self.process_exception_by_middleware(e, request)
  File "/usr/local/lib/python3.5/dist-packages/django/core/handlers/base.py", line 185, in _get_response
    response = wrapped_callback(request, *callback_args, **callback_kwargs)
  File "/home/suyue/opsweb/monitor/views.py", line 130, in abnormal
    ac.valueCheck()
  File "/home/suyue/opsweb/utils/abNormalCheck.py", line 30, in valueCheck
    result=a.get_task()
  File "/home/suyue/opsweb/utils/customMultiprocessingPool.py", line 45, in get_task
    elif not self.__pool_state and self.__pool_state.empty():
AttributeError: 'bool' object has no attribute 'empty'
2018-01-17 19:57:37,359 ERROR    /usr/local/lib/python3.5/dist-packages/django/core/servers/basehttp.py[line:124] "GET /monitor/abnormal/ HTTP/1.0" 500 27
2018-01-17 19:58:42,036 ERROR    /usr/local/lib/python3.5/dist-packages/django/core/handlers/exception.py[line:135] Internal Server Error: /monitor/abnormal/
Traceback (most recent call last):
  File "/usr/local/lib/python3.5/dist-packages/django/core/handlers/exception.py", line 41, in inner
    response = get_response(request)
  File "/usr/local/lib/python3.5/dist-packages/django/core/handlers/base.py", line 187, in _get_response
    response = self.process_exception_by_middleware(e, request)
  File "/usr/local/lib/python3.5/dist-packages/django/core/handlers/base.py", line 185, in _get_response
    response = wrapped_callback(request, *callback_args, **callback_kwargs)
  File "/home/suyue/opsweb/monitor/views.py", line 130, in abnormal
    ac.valueCheck()
  File "/home/suyue/opsweb/utils/abNormalCheck.py", line 30, in valueCheck
    result=a.get_task()
  File "/home/suyue/opsweb/utils/customMultiprocessingPool.py", line 45, in get_task
    elif not self.__pool_state and self.__pool_state.empty():
AttributeError: 'bool' object has no attribute 'empty'
2018-01-17 19:58:42,064 ERROR    /usr/local/lib/python3.5/dist-packages/django/core/servers/basehttp.py[line:124] "GET /monitor/abnormal/ HTTP/1.0" 500 27
2018-01-17 19:59:18,509 ERROR    /usr/local/lib/python3.5/dist-packages/django/core/handlers/exception.py[line:135] Internal Server Error: /monitor/abnormal/
Traceback (most recent call last):
  File "/usr/local/lib/python3.5/dist-packages/django/core/handlers/exception.py", line 41, in inner
    response = get_response(request)
  File "/usr/local/lib/python3.5/dist-packages/django/core/handlers/base.py", line 187, in _get_response
    response = self.process_exception_by_middleware(e, request)
  File "/usr/local/lib/python3.5/dist-packages/django/core/handlers/base.py", line 185, in _get_response
    response = wrapped_callback(request, *callback_args, **callback_kwargs)
  File "/home/suyue/opsweb/monitor/views.py", line 130, in abnormal
    ac.valueCheck()
  File "/home/suyue/opsweb/utils/abNormalCheck.py", line 30, in valueCheck
    result=a.get_task()
  File "/home/suyue/opsweb/utils/customMultiprocessingPool.py", line 45, in get_task
    elif not self.__pool_state and self.__pool_state.empty():
AttributeError: 'bool' object has no attribute 'empty'
2018-01-17 19:59:18,561 ERROR    /usr/local/lib/python3.5/dist-packages/django/core/servers/basehttp.py[line:124] "GET /monitor/abnormal/ HTTP/1.0" 500 27
2018-01-17 20:00:14,735 ERROR    /usr/local/lib/python3.5/dist-packages/django/core/handlers/exception.py[line:135] Internal Server Error: /monitor/abnormal/
Traceback (most recent call last):
  File "/usr/local/lib/python3.5/dist-packages/django/core/handlers/exception.py", line 41, in inner
    response = get_response(request)
  File "/usr/local/lib/python3.5/dist-packages/django/core/handlers/base.py", line 187, in _get_response
    response = self.process_exception_by_middleware(e, request)
  File "/usr/local/lib/python3.5/dist-packages/django/core/handlers/base.py", line 185, in _get_response
    response = wrapped_callback(request, *callback_args, **callback_kwargs)
  File "/home/suyue/opsweb/monitor/views.py", line 130, in abnormal
    ac.valueCheck()
  File "/home/suyue/opsweb/utils/abNormalCheck.py", line 30, in valueCheck
    result=a.get_task()
  File "/home/suyue/opsweb/utils/customMultiprocessingPool.py", line 45, in get_task
    elif not self.__pool_state and self.__pool_state.empty():
AttributeError: 'bool' object has no attribute 'empty'
2018-01-17 20:00:14,742 ERROR    /usr/local/lib/python3.5/dist-packages/django/core/servers/basehttp.py[line:124] "GET /monitor/abnormal/ HTTP/1.0" 500 27
2018-01-19 17:51:21,447 ERROR    /usr/local/lib/python3.5/dist-packages/django/core/handlers/exception.py[line:135] Internal Server Error: /api/deployBackUp/
Traceback (most recent call last):
  File "/usr/local/lib/python3.5/dist-packages/django/core/handlers/exception.py", line 41, in inner
    response = get_response(request)
  File "/usr/local/lib/python3.5/dist-packages/django/core/handlers/base.py", line 187, in _get_response
    response = self.process_exception_by_middleware(e, request)
  File "/usr/local/lib/python3.5/dist-packages/django/core/handlers/base.py", line 185, in _get_response
    response = wrapped_callback(request, *callback_args, **callback_kwargs)
  File "/root/opsweb/api/deploy.py", line 595, in deployOrBackUp
    salt = saltClient()
  File "/root/opsweb/utils/salt_Client.py", line 9, in __init__
    self.__tokenId=self.__login()
  File "/root/opsweb/utils/salt_Client.py", line 16, in __login
    return reslut[0]["token"]
TypeError: 'NoneType' object is not subscriptable
2018-01-19 17:51:21,539 ERROR    /usr/local/lib/python3.5/dist-packages/django/core/servers/basehttp.py[line:124] "POST /api/deployBackUp/ HTTP/1.0" 500 27
2018-02-09 09:50:28,304 ERROR    /usr/local/lib/python3.5/dist-packages/django/core/handlers/exception.py[line:135] Internal Server Error: /monitor/abnormal/
Traceback (most recent call last):
  File "/usr/local/lib/python3.5/dist-packages/django/core/handlers/exception.py", line 41, in inner
    response = get_response(request)
  File "/usr/local/lib/python3.5/dist-packages/django/core/handlers/base.py", line 187, in _get_response
    response = self.process_exception_by_middleware(e, request)
  File "/usr/local/lib/python3.5/dist-packages/django/core/handlers/base.py", line 185, in _get_response
    response = wrapped_callback(request, *callback_args, **callback_kwargs)
  File "/root/opsweb/monitor/views.py", line 130, in abnormal
    ac.valueCheck()
  File "/root/opsweb/utils/abNormalCheck.py", line 22, in valueCheck
    a = Pool(process=10)
TypeError: Pool() got an unexpected keyword argument 'process'
2018-02-09 09:50:28,971 ERROR    /usr/local/lib/python3.5/dist-packages/django/core/servers/basehttp.py[line:124] "GET /monitor/abnormal/ HTTP/1.0" 500 27
2018-02-09 09:51:13,224 ERROR    /usr/local/lib/python3.5/dist-packages/django/core/handlers/exception.py[line:135] Internal Server Error: /monitor/abnormal/
Traceback (most recent call last):
  File "/usr/local/lib/python3.5/dist-packages/django/core/handlers/exception.py", line 41, in inner
    response = get_response(request)
  File "/usr/local/lib/python3.5/dist-packages/django/core/handlers/base.py", line 187, in _get_response
    response = self.process_exception_by_middleware(e, request)
  File "/usr/local/lib/python3.5/dist-packages/django/core/handlers/base.py", line 185, in _get_response
    response = wrapped_callback(request, *callback_args, **callback_kwargs)
  File "/root/opsweb/monitor/views.py", line 130, in abnormal
    ac.valueCheck()
  File "/root/opsweb/utils/abNormalCheck.py", line 24, in valueCheck
    a.add_task(fun=historyGet,args=(item,))
AttributeError: 'ThreadPool' object has no attribute 'add_task'
2018-02-09 09:51:13,240 ERROR    /usr/local/lib/python3.5/dist-packages/django/core/servers/basehttp.py[line:124] "GET /monitor/abnormal/ HTTP/1.0" 500 27
2018-02-09 09:52:36,361 ERROR    /usr/local/lib/python3.5/dist-packages/django/core/handlers/exception.py[line:135] Internal Server Error: /monitor/abnormal/
Traceback (most recent call last):
  File "/usr/local/lib/python3.5/dist-packages/django/core/handlers/exception.py", line 41, in inner
    response = get_response(request)
  File "/usr/local/lib/python3.5/dist-packages/django/core/handlers/base.py", line 187, in _get_response
    response = self.process_exception_by_middleware(e, request)
  File "/usr/local/lib/python3.5/dist-packages/django/core/handlers/base.py", line 185, in _get_response
    response = wrapped_callback(request, *callback_args, **callback_kwargs)
  File "/root/opsweb/monitor/views.py", line 130, in abnormal
    ac.valueCheck()
  File "/root/opsweb/utils/abNormalCheck.py", line 24, in valueCheck
    a.apply_async(fun=historyGet,args=(item,))
TypeError: apply_async() got an unexpected keyword argument 'fun'
2018-02-09 09:52:36,388 ERROR    /usr/local/lib/python3.5/dist-packages/django/core/servers/basehttp.py[line:124] "GET /monitor/abnormal/ HTTP/1.0" 500 27
