2017-08-30 11:17:02,459 WARNING  C:\Program Files\Python36\lib\site-packages\django\core\handlers\base.py[line:152] Not Found: /favicon.ico
2017-08-30 11:17:02,465 WARNING  C:\Program Files\Python36\lib\site-packages\django\core\servers\basehttp.py[line:131] "GET /favicon.ico HTTP/1.1" 404 0
2017-08-30 11:20:42,638 ERROR    C:\Program Files\Python36\lib\site-packages\django\core\handlers\exception.py[line:124] Internal Server Error: /api/zabbix_history_get/
Traceback (most recent call last):
  File "C:\Program Files\Python36\lib\urllib\request.py", line 1318, in do_open
    encode_chunked=req.has_header('Transfer-encoding'))
  File "C:\Program Files\Python36\lib\http\client.py", line 1239, in request
    self._send_request(method, url, body, headers, encode_chunked)
  File "C:\Program Files\Python36\lib\http\client.py", line 1285, in _send_request
    self.endheaders(body, encode_chunked=encode_chunked)
  File "C:\Program Files\Python36\lib\http\client.py", line 1234, in endheaders
    self._send_output(message_body, encode_chunked=encode_chunked)
  File "C:\Program Files\Python36\lib\http\client.py", line 1026, in _send_output
    self.send(msg)
  File "C:\Program Files\Python36\lib\http\client.py", line 964, in send
    self.connect()
  File "C:\Program Files\Python36\lib\http\client.py", line 936, in connect
    (self.host,self.port), self.timeout, self.source_address)
  File "C:\Program Files\Python36\lib\socket.py", line 722, in create_connection
    raise err
  File "C:\Program Files\Python36\lib\socket.py", line 713, in create_connection
    sock.connect(sa)
TimeoutError: [WinError 10060] 由于连接方在一段时间后没有正确答复或连接的主机没有反应，连接尝试失败。

During handling of the above exception, another exception occurred:

Traceback (most recent call last):
  File "C:\Program Files\Python36\lib\site-packages\django\core\handlers\exception.py", line 39, in inner
    response = get_response(request)
  File "C:\Program Files\Python36\lib\site-packages\django\core\handlers\base.py", line 187, in _get_response
    response = self.process_exception_by_middleware(e, request)
  File "C:\Program Files\Python36\lib\site-packages\django\core\handlers\base.py", line 185, in _get_response
    response = wrapped_callback(request, *callback_args, **callback_kwargs)
  File "D:\project\opsweb\api\views.py", line 85, in zabbix_history_get
    zabbix_data_get=zabbix_data()
  File "D:\project\opsweb\utils\zabbix_public_invok.py", line 8, in __init__
    self.__zapi = ZabbixAPI(url=config_value['zabbix_api_addr'][0], user=config_value['zabbix_api_user'][0],password=config_value['zabbix_api_user'][1])
  File "C:\Program Files\Python36\lib\site-packages\pyzabbix\api.py", line 156, in __init__
    self._login(user, password)
  File "C:\Program Files\Python36\lib\site-packages\pyzabbix\api.py", line 186, in _login
    self.auth = self.user.login(user=user, password=password)
  File "C:\Program Files\Python36\lib\site-packages\pyzabbix\api.py", line 82, in fn
    args or kwargs
  File "C:\Program Files\Python36\lib\site-packages\pyzabbix\api.py", line 236, in do_request
    res = urlopen(req)
  File "C:\Program Files\Python36\lib\site-packages\pyzabbix\api.py", line 107, in inner
    res = func(req, context=ctx)
  File "C:\Program Files\Python36\lib\site-packages\pyzabbix\api.py", line 118, in urlopen
    return urllib2.urlopen(*args, **kwargs)
  File "C:\Program Files\Python36\lib\urllib\request.py", line 223, in urlopen
    return opener.open(url, data, timeout)
  File "C:\Program Files\Python36\lib\urllib\request.py", line 526, in open
    response = self._open(req, data)
  File "C:\Program Files\Python36\lib\urllib\request.py", line 544, in _open
    '_open', req)
  File "C:\Program Files\Python36\lib\urllib\request.py", line 504, in _call_chain
    result = func(*args)
  File "C:\Program Files\Python36\lib\urllib\request.py", line 1346, in http_open
    return self.do_open(http.client.HTTPConnection, req)
  File "C:\Program Files\Python36\lib\urllib\request.py", line 1320, in do_open
    raise URLError(err)
urllib.error.URLError: <urlopen error [WinError 10060] 由于连接方在一段时间后没有正确答复或连接的主机没有反应，连接尝试失败。>
2017-08-30 11:20:42,776 ERROR    C:\Program Files\Python36\lib\site-packages\django\core\servers\basehttp.py[line:131] "POST /api/zabbix_history_get/ HTTP/1.1" 500 17895
2017-08-30 11:20:42,798 ERROR    C:\Program Files\Python36\lib\site-packages\django\core\servers\basehttp.py[line:131] "POST /api/zabbix_history_get/ HTTP/1.1" 500 59
2017-08-30 11:22:26,986 WARNING  C:\Program Files\Python36\lib\site-packages\django\core\handlers\base.py[line:152] Not Found: /favicon.ico
2017-08-30 11:22:26,988 WARNING  C:\Program Files\Python36\lib\site-packages\django\core\servers\basehttp.py[line:131] "GET /favicon.ico HTTP/1.1" 404 0
2017-08-30 11:29:09,413 WARNING  C:\Program Files\Python36\lib\site-packages\django\core\handlers\base.py[line:152] Not Found: /favicon.ico
2017-08-30 11:29:09,414 WARNING  C:\Program Files\Python36\lib\site-packages\django\core\servers\basehttp.py[line:131] "GET /favicon.ico HTTP/1.1" 404 0
2017-08-30 11:29:57,546 ERROR    D:\project\opsweb\api\views.py[line:95] 字段历史获取失败<urlopen error [WinError 10060] 由于连接方在一段时间后没有正确答复或连接的主机没有反应，连接尝试失败。>
2017-08-30 11:29:57,546 ERROR    C:\Program Files\Python36\lib\site-packages\django\core\handlers\exception.py[line:124] Internal Server Error: /api/zabbix_history_get/
Traceback (most recent call last):
  File "C:\Program Files\Python36\lib\site-packages\django\core\handlers\exception.py", line 39, in inner
    response = get_response(request)
  File "C:\Program Files\Python36\lib\site-packages\django\core\handlers\base.py", line 187, in _get_response
    response = self.process_exception_by_middleware(e, request)
  File "C:\Program Files\Python36\lib\site-packages\django\core\handlers\base.py", line 185, in _get_response
    response = wrapped_callback(request, *callback_args, **callback_kwargs)
  File "D:\project\opsweb\api\views.py", line 97, in zabbix_history_get
    for item in result:
UnboundLocalError: local variable 'result' referenced before assignment
2017-08-30 11:29:57,577 ERROR    C:\Program Files\Python36\lib\site-packages\django\core\servers\basehttp.py[line:131] "POST /api/zabbix_history_get/ HTTP/1.1" 500 14694
2017-08-30 11:32:58,928 WARNING  C:\Program Files\Python36\lib\site-packages\django\core\handlers\base.py[line:152] Not Found: /favicon.ico
2017-08-30 11:32:58,930 WARNING  C:\Program Files\Python36\lib\site-packages\django\core\servers\basehttp.py[line:131] "GET /favicon.ico HTTP/1.1" 404 0
2017-08-30 11:37:24,125 ERROR    D:\project\opsweb\api\views.py[line:95] 字段历史获取失败<urlopen error [WinError 10060] 由于连接方在一段时间后没有正确答复或连接的主机没有反应，连接尝试失败。>
2017-08-30 11:37:24,126 ERROR    C:\Program Files\Python36\lib\site-packages\django\core\handlers\exception.py[line:124] Internal Server Error: /api/zabbix_history_get/
Traceback (most recent call last):
  File "C:\Program Files\Python36\lib\site-packages\django\core\handlers\exception.py", line 39, in inner
    response = get_response(request)
  File "C:\Program Files\Python36\lib\site-packages\django\core\handlers\base.py", line 187, in _get_response
    response = self.process_exception_by_middleware(e, request)
  File "C:\Program Files\Python36\lib\site-packages\django\core\handlers\base.py", line 185, in _get_response
    response = wrapped_callback(request, *callback_args, **callback_kwargs)
  File "D:\project\opsweb\api\views.py", line 97, in zabbix_history_get
    for item in result:
UnboundLocalError: local variable 'result' referenced before assignment
2017-08-30 11:37:24,163 ERROR    C:\Program Files\Python36\lib\site-packages\django\core\servers\basehttp.py[line:131] "POST /api/zabbix_history_get/ HTTP/1.1" 500 14694
2017-08-30 11:42:11,146 WARNING  C:\Program Files\Python36\lib\site-packages\django\core\handlers\base.py[line:152] Not Found: /favicon.ico
2017-08-30 11:42:11,148 WARNING  C:\Program Files\Python36\lib\site-packages\django\core\servers\basehttp.py[line:131] "GET /favicon.ico HTTP/1.1" 404 0
2017-08-30 11:42:19,822 WARNING  C:\Program Files\Python36\lib\site-packages\django\core\handlers\base.py[line:152] Not Found: /favicon.ico
2017-08-30 11:42:19,824 WARNING  C:\Program Files\Python36\lib\site-packages\django\core\servers\basehttp.py[line:131] "GET /favicon.ico HTTP/1.1" 404 0
2017-08-30 11:43:34,602 ERROR    C:\Program Files\Python36\lib\site-packages\django\core\handlers\exception.py[line:124] Internal Server Error: /monitor/
Traceback (most recent call last):
  File "C:\Program Files\Python36\lib\site-packages\django\core\handlers\exception.py", line 39, in inner
    response = get_response(request)
  File "C:\Program Files\Python36\lib\site-packages\django\core\handlers\base.py", line 187, in _get_response
    response = self.process_exception_by_middleware(e, request)
  File "C:\Program Files\Python36\lib\site-packages\django\core\handlers\base.py", line 185, in _get_response
    response = wrapped_callback(request, *callback_args, **callback_kwargs)
  File "D:\project\opsweb\monitor\views.py", line 26, in index
    zabbix_data_get = zabbix_data()
  File "D:\project\opsweb\utils\zabbix_public_invok.py", line 8, in __init__
    self.__zapi = ZabbixAPI(url=config_value['zabbix_api_addr'][0], user=config_value['zabbix_api_user'][0],password=config_value['zabbix_api_user'][1])
  File "C:\Program Files\Python36\lib\site-packages\pyzabbix\api.py", line 156, in __init__
    self._login(user, password)
  File "C:\Program Files\Python36\lib\site-packages\pyzabbix\api.py", line 186, in _login
    self.auth = self.user.login(user=user, password=password)
  File "C:\Program Files\Python36\lib\site-packages\pyzabbix\api.py", line 82, in fn
    args or kwargs
  File "C:\Program Files\Python36\lib\site-packages\pyzabbix\api.py", line 236, in do_request
    res = urlopen(req)
  File "C:\Program Files\Python36\lib\site-packages\pyzabbix\api.py", line 107, in inner
    res = func(req, context=ctx)
  File "C:\Program Files\Python36\lib\site-packages\pyzabbix\api.py", line 118, in urlopen
    return urllib2.urlopen(*args, **kwargs)
  File "C:\Program Files\Python36\lib\urllib\request.py", line 223, in urlopen
    return opener.open(url, data, timeout)
  File "C:\Program Files\Python36\lib\urllib\request.py", line 532, in open
    response = meth(req, response)
  File "C:\Program Files\Python36\lib\urllib\request.py", line 642, in http_response
    'http', request, response, code, msg, hdrs)
  File "C:\Program Files\Python36\lib\urllib\request.py", line 570, in error
    return self._call_chain(*args)
  File "C:\Program Files\Python36\lib\urllib\request.py", line 504, in _call_chain
    result = func(*args)
  File "C:\Program Files\Python36\lib\urllib\request.py", line 650, in http_error_default
    raise HTTPError(req.full_url, code, msg, hdrs, fp)
urllib.error.HTTPError: HTTP Error 404: Not Found
2017-08-30 11:43:34,806 ERROR    C:\Program Files\Python36\lib\site-packages\django\core\servers\basehttp.py[line:131] "GET /monitor/ HTTP/1.1" 500 125833
2017-08-30 11:43:35,226 WARNING  C:\Program Files\Python36\lib\site-packages\django\core\handlers\base.py[line:152] Not Found: /favicon.ico
2017-08-30 11:43:35,228 WARNING  C:\Program Files\Python36\lib\site-packages\django\core\servers\basehttp.py[line:131] "GET /favicon.ico HTTP/1.1" 404 0
2017-08-30 11:43:42,255 ERROR    C:\Program Files\Python36\lib\site-packages\django\core\handlers\exception.py[line:124] Internal Server Error: /monitor/
Traceback (most recent call last):
  File "C:\Program Files\Python36\lib\site-packages\django\core\handlers\exception.py", line 39, in inner
    response = get_response(request)
  File "C:\Program Files\Python36\lib\site-packages\django\core\handlers\base.py", line 187, in _get_response
    response = self.process_exception_by_middleware(e, request)
  File "C:\Program Files\Python36\lib\site-packages\django\core\handlers\base.py", line 185, in _get_response
    response = wrapped_callback(request, *callback_args, **callback_kwargs)
  File "D:\project\opsweb\monitor\views.py", line 26, in index
    zabbix_data_get = zabbix_data()
  File "D:\project\opsweb\utils\zabbix_public_invok.py", line 8, in __init__
    self.__zapi = ZabbixAPI(url=config_value['zabbix_api_addr'][0], user=config_value['zabbix_api_user'][0],password=config_value['zabbix_api_user'][1])
  File "C:\Program Files\Python36\lib\site-packages\pyzabbix\api.py", line 156, in __init__
    self._login(user, password)
  File "C:\Program Files\Python36\lib\site-packages\pyzabbix\api.py", line 186, in _login
    self.auth = self.user.login(user=user, password=password)
  File "C:\Program Files\Python36\lib\site-packages\pyzabbix\api.py", line 82, in fn
    args or kwargs
  File "C:\Program Files\Python36\lib\site-packages\pyzabbix\api.py", line 236, in do_request
    res = urlopen(req)
  File "C:\Program Files\Python36\lib\site-packages\pyzabbix\api.py", line 107, in inner
    res = func(req, context=ctx)
  File "C:\Program Files\Python36\lib\site-packages\pyzabbix\api.py", line 118, in urlopen
    return urllib2.urlopen(*args, **kwargs)
  File "C:\Program Files\Python36\lib\urllib\request.py", line 223, in urlopen
    return opener.open(url, data, timeout)
  File "C:\Program Files\Python36\lib\urllib\request.py", line 532, in open
    response = meth(req, response)
  File "C:\Program Files\Python36\lib\urllib\request.py", line 642, in http_response
    'http', request, response, code, msg, hdrs)
  File "C:\Program Files\Python36\lib\urllib\request.py", line 570, in error
    return self._call_chain(*args)
  File "C:\Program Files\Python36\lib\urllib\request.py", line 504, in _call_chain
    result = func(*args)
  File "C:\Program Files\Python36\lib\urllib\request.py", line 650, in http_error_default
    raise HTTPError(req.full_url, code, msg, hdrs, fp)
urllib.error.HTTPError: HTTP Error 404: Not Found
2017-08-30 11:43:42,399 ERROR    C:\Program Files\Python36\lib\site-packages\django\core\servers\basehttp.py[line:131] "GET /monitor/ HTTP/1.1" 500 125706
2017-08-30 11:44:25,648 ERROR    C:\Program Files\Python36\lib\site-packages\django\core\handlers\exception.py[line:124] Internal Server Error: /monitor/
Traceback (most recent call last):
  File "C:\Program Files\Python36\lib\site-packages\django\core\handlers\exception.py", line 39, in inner
    response = get_response(request)
  File "C:\Program Files\Python36\lib\site-packages\django\core\handlers\base.py", line 187, in _get_response
    response = self.process_exception_by_middleware(e, request)
  File "C:\Program Files\Python36\lib\site-packages\django\core\handlers\base.py", line 185, in _get_response
    response = wrapped_callback(request, *callback_args, **callback_kwargs)
  File "D:\project\opsweb\monitor\views.py", line 26, in index
    zabbix_data_get = zabbix_data()
  File "D:\project\opsweb\utils\zabbix_public_invok.py", line 8, in __init__
    self.__zapi = ZabbixAPI(url=config_value['zabbix_api_addr'][0], user=config_value['zabbix_api_user'][0],password=config_value['zabbix_api_user'][1])
  File "C:\Program Files\Python36\lib\site-packages\pyzabbix\api.py", line 156, in __init__
    self._login(user, password)
  File "C:\Program Files\Python36\lib\site-packages\pyzabbix\api.py", line 186, in _login
    self.auth = self.user.login(user=user, password=password)
  File "C:\Program Files\Python36\lib\site-packages\pyzabbix\api.py", line 82, in fn
    args or kwargs
  File "C:\Program Files\Python36\lib\site-packages\pyzabbix\api.py", line 250, in do_request
    raise ZabbixAPIException(msg, err['code'])
pyzabbix.api.ZabbixAPIException: ("Error -32602: Invalid params., Login name or password is incorrect. while sending {'jsonrpc': '2.0', 'method': 'user.login', 'params': {'user': 'admi', 'password': 'f#t@2016zabbix'}, 'id': '1'}", -32602)
2017-08-30 11:44:25,732 ERROR    C:\Program Files\Python36\lib\site-packages\django\core\servers\basehttp.py[line:131] "GET /monitor/ HTTP/1.1" 500 91336
2017-08-30 11:53:41,670 WARNING  C:\Program Files\Python36\lib\site-packages\django\core\handlers\base.py[line:152] Not Found: /favicon.ico
2017-08-30 11:53:41,672 WARNING  C:\Program Files\Python36\lib\site-packages\django\core\servers\basehttp.py[line:131] "GET /favicon.ico HTTP/1.1" 404 0
2017-08-30 11:53:44,765 WARNING  C:\Program Files\Python36\lib\site-packages\django\core\handlers\base.py[line:152] Not Found: /api/zabbix_history_ge/
2017-08-30 11:53:44,767 WARNING  C:\Program Files\Python36\lib\site-packages\django\core\servers\basehttp.py[line:131] "POST /api/zabbix_history_ge/ HTTP/1.1" 404 0
2017-08-30 11:53:53,509 WARNING  C:\Program Files\Python36\lib\site-packages\django\core\handlers\base.py[line:152] Not Found: /api/zabbix_history_ge/
2017-08-30 11:53:53,513 WARNING  C:\Program Files\Python36\lib\site-packages\django\core\servers\basehttp.py[line:131] "POST /api/zabbix_history_ge/ HTTP/1.1" 404 0
2017-08-30 11:55:24,767 ERROR    C:\Program Files\Python36\lib\site-packages\django\core\servers\basehttp.py[line:131] "POST /api/nginxLog/ HTTP/1.1" 500 59
2017-08-30 11:55:24,875 ERROR    C:\Program Files\Python36\lib\site-packages\django\core\servers\basehttp.py[line:131] "POST /api/nginxLog/ HTTP/1.1" 500 59
2017-08-30 11:55:25,279 ERROR    C:\Program Files\Python36\lib\site-packages\django\core\servers\basehttp.py[line:131] "POST /api/nginxLog/ HTTP/1.1" 500 59
2017-08-30 14:36:09,613 WARNING  C:\Program Files\Python36\lib\site-packages\django\core\handlers\base.py[line:152] Not Found: /favicon.ico
2017-08-30 14:36:09,614 WARNING  C:\Program Files\Python36\lib\site-packages\django\core\servers\basehttp.py[line:131] "GET /favicon.ico HTTP/1.1" 404 0
2017-08-30 14:36:41,764 WARNING  C:\Program Files\Python36\lib\site-packages\django\core\handlers\base.py[line:152] Not Found: /favicon.ico
2017-08-30 14:36:41,765 WARNING  C:\Program Files\Python36\lib\site-packages\django\core\servers\basehttp.py[line:131] "GET /favicon.ico HTTP/1.1" 404 0
2017-08-30 14:36:42,734 WARNING  C:\Program Files\Python36\lib\site-packages\django\core\handlers\base.py[line:152] Not Found: /favicon.ico
2017-08-30 14:36:42,735 WARNING  C:\Program Files\Python36\lib\site-packages\django\core\servers\basehttp.py[line:131] "GET /favicon.ico HTTP/1.1" 404 0
2017-08-30 14:38:06,962 WARNING  C:\Program Files\Python36\lib\site-packages\django\core\handlers\base.py[line:152] Not Found: /favicon.ico
2017-08-30 14:38:06,964 WARNING  C:\Program Files\Python36\lib\site-packages\django\core\servers\basehttp.py[line:131] "GET /favicon.ico HTTP/1.1" 404 0
2017-08-30 14:41:55,737 WARNING  C:\Program Files\Python36\lib\site-packages\django\core\handlers\base.py[line:152] Not Found: /favicon.ico
2017-08-30 14:41:55,739 WARNING  C:\Program Files\Python36\lib\site-packages\django\core\servers\basehttp.py[line:131] "GET /favicon.ico HTTP/1.1" 404 0
2017-08-30 14:42:30,325 WARNING  C:\Program Files\Python36\lib\site-packages\django\core\handlers\base.py[line:152] Not Found: /favicon.ico
2017-08-30 14:42:30,327 WARNING  C:\Program Files\Python36\lib\site-packages\django\core\servers\basehttp.py[line:131] "GET /favicon.ico HTTP/1.1" 404 0
2017-08-30 14:45:17,542 WARNING  C:\Program Files\Python36\lib\site-packages\django\core\handlers\base.py[line:152] Not Found: /favicon.ico
2017-08-30 14:45:17,543 WARNING  C:\Program Files\Python36\lib\site-packages\django\core\servers\basehttp.py[line:131] "GET /favicon.ico HTTP/1.1" 404 0
2017-08-30 14:47:33,592 WARNING  C:\Program Files\Python36\lib\site-packages\django\core\handlers\base.py[line:152] Not Found: /favicon.ico
2017-08-30 14:47:33,598 WARNING  C:\Program Files\Python36\lib\site-packages\django\core\servers\basehttp.py[line:131] "GET /favicon.ico HTTP/1.1" 404 0
2017-08-30 14:49:03,420 WARNING  C:\Program Files\Python36\lib\site-packages\django\core\handlers\base.py[line:152] Not Found: /favicon.ico
2017-08-30 14:49:03,422 WARNING  C:\Program Files\Python36\lib\site-packages\django\core\servers\basehttp.py[line:131] "GET /favicon.ico HTTP/1.1" 404 0
2017-08-30 15:07:14,002 WARNING  C:\Program Files\Python36\lib\site-packages\django\core\handlers\base.py[line:152] Not Found: /favicon.ico
2017-08-30 15:07:14,004 WARNING  C:\Program Files\Python36\lib\site-packages\django\core\servers\basehttp.py[line:131] "GET /favicon.ico HTTP/1.1" 404 0
2017-08-30 15:08:22,196 WARNING  C:\Program Files\Python36\lib\site-packages\django\core\handlers\base.py[line:152] Not Found: /favicon.ico
2017-08-30 15:08:22,199 WARNING  C:\Program Files\Python36\lib\site-packages\django\core\servers\basehttp.py[line:131] "GET /favicon.ico HTTP/1.1" 404 0
2017-08-30 15:08:41,244 WARNING  C:\Program Files\Python36\lib\site-packages\django\core\handlers\base.py[line:152] Not Found: /favicon.ico
2017-08-30 15:08:41,246 WARNING  C:\Program Files\Python36\lib\site-packages\django\core\servers\basehttp.py[line:131] "GET /favicon.ico HTTP/1.1" 404 0
2017-08-30 15:11:23,601 WARNING  C:\Program Files\Python36\lib\site-packages\django\core\handlers\base.py[line:152] Not Found: /favicon.ico
2017-08-30 15:11:23,602 WARNING  C:\Program Files\Python36\lib\site-packages\django\core\servers\basehttp.py[line:131] "GET /favicon.ico HTTP/1.1" 404 0
2017-08-30 15:18:23,322 WARNING  C:\Program Files\Python36\lib\site-packages\django\core\handlers\base.py[line:152] Not Found: /favicon.ico
2017-08-30 15:18:23,324 WARNING  C:\Program Files\Python36\lib\site-packages\django\core\servers\basehttp.py[line:131] "GET /favicon.ico HTTP/1.1" 404 0
2017-08-30 15:18:28,970 WARNING  C:\Program Files\Python36\lib\site-packages\django\core\handlers\base.py[line:152] Not Found: /favicon.ico
2017-08-30 15:18:28,971 WARNING  C:\Program Files\Python36\lib\site-packages\django\core\servers\basehttp.py[line:131] "GET /favicon.ico HTTP/1.1" 404 0
2017-08-30 15:18:36,292 WARNING  C:\Program Files\Python36\lib\site-packages\django\core\handlers\base.py[line:152] Not Found: /favicon.ico
2017-08-30 15:18:36,294 WARNING  C:\Program Files\Python36\lib\site-packages\django\core\servers\basehttp.py[line:131] "GET /favicon.ico HTTP/1.1" 404 0
2017-08-30 15:44:13,300 WARNING  C:\Program Files\Python36\lib\site-packages\django\core\handlers\base.py[line:152] Not Found: /favicon.ico
2017-08-30 15:44:13,302 WARNING  C:\Program Files\Python36\lib\site-packages\django\core\servers\basehttp.py[line:131] "GET /favicon.ico HTTP/1.1" 404 0
2017-08-30 15:46:49,789 WARNING  C:\Program Files\Python36\lib\site-packages\django\core\handlers\base.py[line:152] Not Found: /favicon.ico
2017-08-30 15:46:49,791 WARNING  C:\Program Files\Python36\lib\site-packages\django\core\servers\basehttp.py[line:131] "GET /favicon.ico HTTP/1.1" 404 0
2017-08-30 15:46:59,966 WARNING  C:\Program Files\Python36\lib\site-packages\django\core\handlers\base.py[line:152] Not Found: /favicon.ico
2017-08-30 15:46:59,967 WARNING  C:\Program Files\Python36\lib\site-packages\django\core\servers\basehttp.py[line:131] "GET /favicon.ico HTTP/1.1" 404 0
2017-08-30 16:27:31,499 ERROR    C:\Program Files\Python36\lib\site-packages\django\core\handlers\exception.py[line:124] Internal Server Error: /log/luceneCustomQuery/
Traceback (most recent call last):
  File "C:\Program Files\Python36\lib\site-packages\urllib3\connectionpool.py", line 386, in _make_request
    six.raise_from(e, None)
  File "<string>", line 2, in raise_from
  File "C:\Program Files\Python36\lib\site-packages\urllib3\connectionpool.py", line 382, in _make_request
    httplib_response = conn.getresponse()
  File "C:\Program Files\Python36\lib\http\client.py", line 1331, in getresponse
    response.begin()
  File "C:\Program Files\Python36\lib\http\client.py", line 297, in begin
    version, status, reason = self._read_status()
  File "C:\Program Files\Python36\lib\http\client.py", line 258, in _read_status
    line = str(self.fp.readline(_MAXLINE + 1), "iso-8859-1")
  File "C:\Program Files\Python36\lib\socket.py", line 586, in readinto
    return self._sock.recv_into(b)
socket.timeout: timed out

During handling of the above exception, another exception occurred:

Traceback (most recent call last):
  File "C:\Program Files\Python36\lib\site-packages\elasticsearch\connection\http_urllib3.py", line 114, in perform_request
    response = self.pool.urlopen(method, url, body, retries=False, headers=self.headers, **kw)
  File "C:\Program Files\Python36\lib\site-packages\urllib3\connectionpool.py", line 649, in urlopen
    _stacktrace=sys.exc_info()[2])
  File "C:\Program Files\Python36\lib\site-packages\urllib3\util\retry.py", line 333, in increment
    raise six.reraise(type(error), error, _stacktrace)
  File "C:\Program Files\Python36\lib\site-packages\urllib3\packages\six.py", line 686, in reraise
    raise value
  File "C:\Program Files\Python36\lib\site-packages\urllib3\connectionpool.py", line 600, in urlopen
    chunked=chunked)
  File "C:\Program Files\Python36\lib\site-packages\urllib3\connectionpool.py", line 388, in _make_request
    self._raise_timeout(err=e, url=url, timeout_value=read_timeout)
  File "C:\Program Files\Python36\lib\site-packages\urllib3\connectionpool.py", line 308, in _raise_timeout
    raise ReadTimeoutError(self, url, "Read timed out. (read timeout=%s)" % timeout_value)
urllib3.exceptions.ReadTimeoutError: HTTPConnectionPool(host='10.168.157.75', port=9200): Read timed out. (read timeout=30)

During handling of the above exception, another exception occurred:

Traceback (most recent call last):
  File "C:\Program Files\Python36\lib\site-packages\django\core\handlers\exception.py", line 39, in inner
    response = get_response(request)
  File "C:\Program Files\Python36\lib\site-packages\django\core\handlers\base.py", line 187, in _get_response
    response = self.process_exception_by_middleware(e, request)
  File "C:\Program Files\Python36\lib\site-packages\django\core\handlers\base.py", line 185, in _get_response
    response = wrapped_callback(request, *callback_args, **callback_kwargs)
  File "D:\project\opsweb\log\views.py", line 14, in luceneQuery
    result = es.indexQuery('*')
  File "D:\project\opsweb\utils\ElsInvok.py", line 16, in indexQuery
    return self.__ElscApi.indices.get(index=index)
  File "C:\Program Files\Python36\lib\site-packages\elasticsearch\client\utils.py", line 73, in _wrapped
    return func(*args, params=params, **kwargs)
  File "C:\Program Files\Python36\lib\site-packages\elasticsearch\client\indices.py", line 135, in get
    feature), params=params)
  File "C:\Program Files\Python36\lib\site-packages\elasticsearch\transport.py", line 312, in perform_request
    status, headers, data = connection.perform_request(method, url, params, body, ignore=ignore, timeout=timeout)
  File "C:\Program Files\Python36\lib\site-packages\elasticsearch\connection\http_urllib3.py", line 122, in perform_request
    raise ConnectionTimeout('TIMEOUT', str(e), e)
elasticsearch.exceptions.ConnectionTimeout: ConnectionTimeout caused by - ReadTimeoutError(HTTPConnectionPool(host='10.168.157.75', port=9200): Read timed out. (read timeout=30))
2017-08-30 16:27:31,725 ERROR    C:\Program Files\Python36\lib\site-packages\django\core\servers\basehttp.py[line:131] "GET /log/luceneCustomQuery/ HTTP/1.1" 500 156911
2017-08-30 16:27:31,729 ERROR    C:\Program Files\Python36\lib\site-packages\django\core\servers\basehttp.py[line:131] "GET /log/luceneCustomQuery/ HTTP/1.1" 500 59
2017-09-01 13:04:21,334 WARNING  C:\Program Files\Python36\lib\site-packages\django\core\handlers\base.py[line:152] Not Found: /favicon.ico
2017-09-01 13:04:21,366 WARNING  C:\Program Files\Python36\lib\site-packages\django\core\servers\basehttp.py[line:131] "GET /favicon.ico HTTP/1.1" 404 0
2017-09-07 11:04:58,066 WARNING  C:\Program Files\Python36\lib\site-packages\django\core\handlers\base.py[line:152] Not Found: /favicon.ico
2017-09-07 11:04:58,082 WARNING  C:\Program Files\Python36\lib\site-packages\django\core\servers\basehttp.py[line:131] "GET /favicon.ico HTTP/1.1" 404 0
2017-09-07 11:05:06,687 ERROR    C:\Program Files\Python36\lib\site-packages\django\core\handlers\exception.py[line:124] Internal Server Error: /monitor/
Traceback (most recent call last):
  File "C:\Program Files\Python36\lib\site-packages\django\core\handlers\exception.py", line 39, in inner
    response = get_response(request)
  File "D:\project\opsweb\user\auth.py", line 51, in __call__
    return response
UnboundLocalError: local variable 'response' referenced before assignment
2017-09-07 11:05:06,820 ERROR    C:\Program Files\Python36\lib\site-packages\django\core\servers\basehttp.py[line:131] "GET /monitor/ HTTP/1.1" 500 53688
2017-09-07 11:06:25,404 ERROR    C:\Program Files\Python36\lib\site-packages\django\core\handlers\exception.py[line:124] Internal Server Error: /monitor/
Traceback (most recent call last):
  File "C:\Program Files\Python36\lib\site-packages\django\core\handlers\exception.py", line 39, in inner
    response = get_response(request)
  File "D:\project\opsweb\user\auth.py", line 50, in __call__
    return response
UnboundLocalError: local variable 'response' referenced before assignment
2017-09-07 11:06:25,483 ERROR    C:\Program Files\Python36\lib\site-packages\django\core\servers\basehttp.py[line:131] "GET /monitor/ HTTP/1.1" 500 53669
2017-09-07 11:06:40,424 ERROR    C:\Program Files\Python36\lib\site-packages\django\core\handlers\exception.py[line:124] Internal Server Error: /monitor/
Traceback (most recent call last):
  File "C:\Program Files\Python36\lib\site-packages\django\core\handlers\exception.py", line 39, in inner
    response = get_response(request)
  File "D:\project\opsweb\user\auth.py", line 51, in __call__
    return response
UnboundLocalError: local variable 'response' referenced before assignment
2017-09-07 11:06:40,484 ERROR    C:\Program Files\Python36\lib\site-packages\django\core\servers\basehttp.py[line:131] "GET /monitor/ HTTP/1.1" 500 53795
2017-09-07 11:06:40,608 WARNING  C:\Program Files\Python36\lib\site-packages\django\core\handlers\base.py[line:152] Not Found: /favicon.ico
2017-09-07 11:06:40,615 WARNING  C:\Program Files\Python36\lib\site-packages\django\core\servers\basehttp.py[line:131] "GET /favicon.ico HTTP/1.1" 404 0
2017-09-07 11:20:41,591 WARNING  C:\Program Files\Python36\lib\site-packages\django\core\servers\basehttp.py[line:131] "GET /monitor/ HTTP/1.1" 403 0
2017-09-07 11:20:43,046 WARNING  C:\Program Files\Python36\lib\site-packages\django\core\servers\basehttp.py[line:131] "GET /monitor/ HTTP/1.1" 403 0
2017-09-07 11:20:52,976 WARNING  C:\Program Files\Python36\lib\site-packages\django\core\handlers\base.py[line:152] Not Found: /favicon.ico
2017-09-07 11:20:52,977 WARNING  C:\Program Files\Python36\lib\site-packages\django\core\servers\basehttp.py[line:131] "GET /favicon.ico HTTP/1.1" 404 0
2017-09-07 11:36:25,159 WARNING  C:\Program Files\Python36\lib\site-packages\django\core\servers\basehttp.py[line:131] "GET /monitor/ HTTP/1.1" 403 0
2017-09-07 11:46:28,737 ERROR    C:\Program Files\Python36\lib\site-packages\django\core\handlers\exception.py[line:124] Internal Server Error: /user/Login/
Traceback (most recent call last):
  File "C:\Program Files\Python36\lib\site-packages\django\core\handlers\exception.py", line 39, in inner
    response = get_response(request)
  File "C:\Program Files\Python36\lib\site-packages\django\core\handlers\base.py", line 187, in _get_response
    response = self.process_exception_by_middleware(e, request)
  File "C:\Program Files\Python36\lib\site-packages\django\core\handlers\base.py", line 185, in _get_response
    response = wrapped_callback(request, *callback_args, **callback_kwargs)
  File "D:\project\opsweb\user\login.py", line 16, in login_post
    print(request.session.level)
AttributeError: 'SessionStore' object has no attribute 'level'
2017-09-07 11:46:28,809 ERROR    C:\Program Files\Python36\lib\site-packages\django\core\servers\basehttp.py[line:131] "POST /user/Login/ HTTP/1.1" 500 66604
2017-09-07 14:52:34,114 WARNING  C:\Program Files\Python36\lib\site-packages\django\core\handlers\base.py[line:152] Not Found: /favicon.ico
2017-09-07 14:52:34,116 WARNING  C:\Program Files\Python36\lib\site-packages\django\core\servers\basehttp.py[line:131] "GET /favicon.ico HTTP/1.1" 404 0
2017-09-07 14:52:50,806 WARNING  C:\Program Files\Python36\lib\site-packages\django\core\handlers\base.py[line:152] Not Found: /favicon.ico
2017-09-07 14:52:50,809 WARNING  C:\Program Files\Python36\lib\site-packages\django\core\servers\basehttp.py[line:131] "GET /favicon.ico HTTP/1.1" 404 0
2017-09-07 15:22:10,666 WARNING  C:\Program Files\Python36\lib\site-packages\django\core\servers\basehttp.py[line:131] "POST /api/TomcatThriftLog/ HTTP/1.1" 403 0
2017-09-07 15:22:18,156 WARNING  C:\Program Files\Python36\lib\site-packages\django\core\servers\basehttp.py[line:131] "POST /api/TomcatThriftLog/ HTTP/1.1" 403 0
2017-09-07 15:22:18,190 WARNING  C:\Program Files\Python36\lib\site-packages\django\core\handlers\base.py[line:152] Not Found: /favicon.ico
2017-09-07 15:22:18,192 WARNING  C:\Program Files\Python36\lib\site-packages\django\core\servers\basehttp.py[line:131] "GET /favicon.ico HTTP/1.1" 404 0
2017-09-07 15:22:38,084 WARNING  C:\Program Files\Python36\lib\site-packages\django\core\servers\basehttp.py[line:131] "POST /api/TomcatThriftLog/ HTTP/1.1" 403 0
2017-09-07 15:26:09,821 ERROR    C:\Program Files\Python36\lib\site-packages\django\core\servers\basehttp.py[line:131] "POST /api/zabbix_history_get/ HTTP/1.1" 500 59
2017-09-07 15:29:01,680 ERROR    D:\project\opsweb\api\views.py[line:456] nginx日志获取失败ConnectionTimeout caused by - ReadTimeoutError(HTTPConnectionPool(host='10.168.157.75', port=9200): Read timed out. (read timeout=30))
2017-09-07 15:29:01,682 ERROR    C:\Program Files\Python36\lib\site-packages\django\core\handlers\exception.py[line:124] Internal Server Error: /api/nginxLog/
Traceback (most recent call last):
  File "C:\Program Files\Python36\lib\site-packages\django\core\handlers\exception.py", line 39, in inner
    response = get_response(request)
  File "C:\Program Files\Python36\lib\site-packages\django\core\handlers\base.py", line 198, in _get_response
    "returned None instead." % (callback.__module__, view_name)
ValueError: The view api.views.nginxLog didn't return an HttpResponse object. It returned None instead.
2017-09-07 15:29:01,684 ERROR    D:\project\opsweb\api\views.py[line:456] nginx日志获取失败ConnectionTimeout caused by - ReadTimeoutError(HTTPConnectionPool(host='10.168.157.75', port=9200): Read timed out. (read timeout=30))
2017-09-07 15:29:01,703 ERROR    C:\Program Files\Python36\lib\site-packages\django\core\servers\basehttp.py[line:131] "POST /api/nginxLog/ HTTP/1.1" 500 14430
2017-09-07 15:29:01,706 ERROR    D:\project\opsweb\api\views.py[line:456] nginx日志获取失败ConnectionTimeout caused by - ReadTimeoutError(HTTPConnectionPool(host='10.168.157.75', port=9200): Read timed out. (read timeout=30))
2017-09-07 15:29:01,711 ERROR    C:\Program Files\Python36\lib\site-packages\django\core\handlers\exception.py[line:124] Internal Server Error: /api/nginxLog/
Traceback (most recent call last):
  File "C:\Program Files\Python36\lib\site-packages\django\core\handlers\exception.py", line 39, in inner
    response = get_response(request)
  File "C:\Program Files\Python36\lib\site-packages\django\core\handlers\base.py", line 198, in _get_response
    "returned None instead." % (callback.__module__, view_name)
ValueError: The view api.views.nginxLog didn't return an HttpResponse object. It returned None instead.
2017-09-07 15:29:01,752 ERROR    C:\Program Files\Python36\lib\site-packages\django\core\handlers\exception.py[line:124] Internal Server Error: /api/nginxLog/
Traceback (most recent call last):
  File "C:\Program Files\Python36\lib\site-packages\django\core\handlers\exception.py", line 39, in inner
    response = get_response(request)
  File "C:\Program Files\Python36\lib\site-packages\django\core\handlers\base.py", line 198, in _get_response
    "returned None instead." % (callback.__module__, view_name)
ValueError: The view api.views.nginxLog didn't return an HttpResponse object. It returned None instead.
2017-09-07 15:29:01,827 ERROR    C:\Program Files\Python36\lib\site-packages\django\core\servers\basehttp.py[line:131] "POST /api/nginxLog/ HTTP/1.1" 500 14430
2017-09-07 15:29:01,849 ERROR    C:\Program Files\Python36\lib\site-packages\django\core\servers\basehttp.py[line:131] "POST /api/nginxLog/ HTTP/1.1" 500 14430
2017-09-07 15:29:39,271 ERROR    D:\project\opsweb\api\views.py[line:456] nginx日志获取失败ConnectionTimeout caused by - ReadTimeoutError(HTTPConnectionPool(host='10.168.157.75', port=9200): Read timed out. (read timeout=30))
2017-09-07 15:29:39,271 ERROR    C:\Program Files\Python36\lib\site-packages\django\core\handlers\exception.py[line:124] Internal Server Error: /api/nginxLog/
Traceback (most recent call last):
  File "C:\Program Files\Python36\lib\site-packages\django\core\handlers\exception.py", line 39, in inner
    response = get_response(request)
  File "C:\Program Files\Python36\lib\site-packages\django\core\handlers\base.py", line 198, in _get_response
    "returned None instead." % (callback.__module__, view_name)
ValueError: The view api.views.nginxLog didn't return an HttpResponse object. It returned None instead.
2017-09-07 15:29:39,293 ERROR    C:\Program Files\Python36\lib\site-packages\django\core\servers\basehttp.py[line:131] "POST /api/nginxLog/ HTTP/1.1" 500 14430
2017-09-07 15:29:39,320 ERROR    D:\project\opsweb\api\views.py[line:456] nginx日志获取失败ConnectionTimeout caused by - ReadTimeoutError(HTTPConnectionPool(host='10.168.157.75', port=9200): Read timed out. (read timeout=30))
2017-09-07 15:29:39,325 ERROR    C:\Program Files\Python36\lib\site-packages\django\core\handlers\exception.py[line:124] Internal Server Error: /api/nginxLog/
Traceback (most recent call last):
  File "C:\Program Files\Python36\lib\site-packages\django\core\handlers\exception.py", line 39, in inner
    response = get_response(request)
  File "C:\Program Files\Python36\lib\site-packages\django\core\handlers\base.py", line 198, in _get_response
    "returned None instead." % (callback.__module__, view_name)
ValueError: The view api.views.nginxLog didn't return an HttpResponse object. It returned None instead.
2017-09-07 15:29:39,328 ERROR    D:\project\opsweb\api\views.py[line:456] nginx日志获取失败ConnectionTimeout caused by - ReadTimeoutError(HTTPConnectionPool(host='10.168.157.75', port=9200): Read timed out. (read timeout=30))
2017-09-07 15:29:39,338 ERROR    C:\Program Files\Python36\lib\site-packages\django\core\handlers\exception.py[line:124] Internal Server Error: /api/nginxLog/
Traceback (most recent call last):
  File "C:\Program Files\Python36\lib\site-packages\django\core\handlers\exception.py", line 39, in inner
    response = get_response(request)
  File "C:\Program Files\Python36\lib\site-packages\django\core\handlers\base.py", line 198, in _get_response
    "returned None instead." % (callback.__module__, view_name)
ValueError: The view api.views.nginxLog didn't return an HttpResponse object. It returned None instead.
2017-09-07 15:29:39,363 ERROR    C:\Program Files\Python36\lib\site-packages\django\core\servers\basehttp.py[line:131] "POST /api/nginxLog/ HTTP/1.1" 500 14430
2017-09-07 15:29:39,392 ERROR    C:\Program Files\Python36\lib\site-packages\django\core\servers\basehttp.py[line:131] "POST /api/nginxLog/ HTTP/1.1" 500 14430
2017-09-07 15:30:25,318 ERROR    D:\project\opsweb\api\views.py[line:456] nginx日志获取失败ConnectionTimeout caused by - ReadTimeoutError(HTTPConnectionPool(host='10.168.157.75', port=9200): Read timed out. (read timeout=30))
2017-09-07 15:30:25,320 ERROR    C:\Program Files\Python36\lib\site-packages\django\core\handlers\exception.py[line:124] Internal Server Error: /api/nginxLog/
Traceback (most recent call last):
  File "C:\Program Files\Python36\lib\site-packages\django\core\handlers\exception.py", line 39, in inner
    response = get_response(request)
  File "C:\Program Files\Python36\lib\site-packages\django\core\handlers\base.py", line 198, in _get_response
    "returned None instead." % (callback.__module__, view_name)
ValueError: The view api.views.nginxLog didn't return an HttpResponse object. It returned None instead.
2017-09-07 15:30:25,322 ERROR    D:\project\opsweb\api\views.py[line:456] nginx日志获取失败ConnectionTimeout caused by - ReadTimeoutError(HTTPConnectionPool(host='10.168.157.75', port=9200): Read timed out. (read timeout=30))
2017-09-07 15:30:25,353 ERROR    C:\Program Files\Python36\lib\site-packages\django\core\handlers\exception.py[line:124] Internal Server Error: /api/nginxLog/
Traceback (most recent call last):
  File "C:\Program Files\Python36\lib\site-packages\django\core\handlers\exception.py", line 39, in inner
    response = get_response(request)
  File "C:\Program Files\Python36\lib\site-packages\django\core\handlers\base.py", line 198, in _get_response
    "returned None instead." % (callback.__module__, view_name)
ValueError: The view api.views.nginxLog didn't return an HttpResponse object. It returned None instead.
2017-09-07 15:30:25,352 ERROR    C:\Program Files\Python36\lib\site-packages\django\core\servers\basehttp.py[line:131] "POST /api/nginxLog/ HTTP/1.1" 500 14430
2017-09-07 15:30:25,373 ERROR    C:\Program Files\Python36\lib\site-packages\django\core\servers\basehttp.py[line:131] "POST /api/nginxLog/ HTTP/1.1" 500 14430
2017-09-07 15:30:25,373 ERROR    D:\project\opsweb\api\views.py[line:456] nginx日志获取失败ConnectionTimeout caused by - ReadTimeoutError(HTTPConnectionPool(host='10.168.157.75', port=9200): Read timed out. (read timeout=30))
2017-09-07 15:30:25,376 ERROR    C:\Program Files\Python36\lib\site-packages\django\core\handlers\exception.py[line:124] Internal Server Error: /api/nginxLog/
Traceback (most recent call last):
  File "C:\Program Files\Python36\lib\site-packages\django\core\handlers\exception.py", line 39, in inner
    response = get_response(request)
  File "C:\Program Files\Python36\lib\site-packages\django\core\handlers\base.py", line 198, in _get_response
    "returned None instead." % (callback.__module__, view_name)
ValueError: The view api.views.nginxLog didn't return an HttpResponse object. It returned None instead.
2017-09-07 15:30:25,398 ERROR    C:\Program Files\Python36\lib\site-packages\django\core\servers\basehttp.py[line:131] "POST /api/nginxLog/ HTTP/1.1" 500 14430
2017-09-07 15:30:52,853 ERROR    D:\project\opsweb\api\views.py[line:244] 通过scrollId获取信息失败ConnectionTimeout caused by - ReadTimeoutError(HTTPConnectionPool(host='10.168.157.75', port=9200): Read timed out. (read timeout=30))
2017-09-07 15:32:38,064 ERROR    D:\project\opsweb\api\views.py[line:456] nginx日志获取失败ConnectionTimeout caused by - ReadTimeoutError(HTTPConnectionPool(host='10.168.157.75', port=9200): Read timed out. (read timeout=30))
2017-09-07 15:32:38,066 ERROR    C:\Program Files\Python36\lib\site-packages\django\core\handlers\exception.py[line:124] Internal Server Error: /api/nginxLog/
Traceback (most recent call last):
  File "C:\Program Files\Python36\lib\site-packages\django\core\handlers\exception.py", line 39, in inner
    response = get_response(request)
  File "C:\Program Files\Python36\lib\site-packages\django\core\handlers\base.py", line 198, in _get_response
    "returned None instead." % (callback.__module__, view_name)
ValueError: The view api.views.nginxLog didn't return an HttpResponse object. It returned None instead.
2017-09-07 15:32:38,068 ERROR    D:\project\opsweb\api\views.py[line:456] nginx日志获取失败ConnectionTimeout caused by - ReadTimeoutError(HTTPConnectionPool(host='10.168.157.75', port=9200): Read timed out. (read timeout=30))
2017-09-07 15:32:38,074 ERROR    C:\Program Files\Python36\lib\site-packages\django\core\handlers\exception.py[line:124] Internal Server Error: /api/nginxLog/
Traceback (most recent call last):
  File "C:\Program Files\Python36\lib\site-packages\django\core\handlers\exception.py", line 39, in inner
    response = get_response(request)
  File "C:\Program Files\Python36\lib\site-packages\django\core\handlers\base.py", line 198, in _get_response
    "returned None instead." % (callback.__module__, view_name)
ValueError: The view api.views.nginxLog didn't return an HttpResponse object. It returned None instead.
2017-09-07 15:32:38,088 ERROR    C:\Program Files\Python36\lib\site-packages\django\core\servers\basehttp.py[line:131] "POST /api/nginxLog/ HTTP/1.1" 500 14431
2017-09-07 15:32:38,096 ERROR    D:\project\opsweb\api\views.py[line:456] nginx日志获取失败ConnectionTimeout caused by - ReadTimeoutError(HTTPConnectionPool(host='10.168.157.75', port=9200): Read timed out. (read timeout=30))
2017-09-07 15:32:38,111 ERROR    C:\Program Files\Python36\lib\site-packages\django\core\servers\basehttp.py[line:131] "POST /api/nginxLog/ HTTP/1.1" 500 14431
2017-09-07 15:32:38,113 ERROR    C:\Program Files\Python36\lib\site-packages\django\core\handlers\exception.py[line:124] Internal Server Error: /api/nginxLog/
Traceback (most recent call last):
  File "C:\Program Files\Python36\lib\site-packages\django\core\handlers\exception.py", line 39, in inner
    response = get_response(request)
  File "C:\Program Files\Python36\lib\site-packages\django\core\handlers\base.py", line 198, in _get_response
    "returned None instead." % (callback.__module__, view_name)
ValueError: The view api.views.nginxLog didn't return an HttpResponse object. It returned None instead.
2017-09-07 15:32:38,147 ERROR    C:\Program Files\Python36\lib\site-packages\django\core\servers\basehttp.py[line:131] "POST /api/nginxLog/ HTTP/1.1" 500 14430
2017-09-07 15:43:16,777 WARNING  C:\Program Files\Python36\lib\site-packages\django\core\handlers\base.py[line:152] Not Found: /favicon.ico
2017-09-07 15:43:16,778 WARNING  C:\Program Files\Python36\lib\site-packages\django\core\servers\basehttp.py[line:131] "GET /favicon.ico HTTP/1.1" 404 0
