2017-08-02 14:50:00,827 WARNING  C:\Program Files\Python36\lib\site-packages\django\core\handlers\base.py[line:152] Not Found: /favicon.ico
2017-08-02 14:50:00,833 WARNING  C:\Program Files\Python36\lib\site-packages\django\core\servers\basehttp.py[line:131] "GET /favicon.ico HTTP/1.1" 404 0
2017-08-02 14:51:24,563 ERROR    D:\project\opsweb\api\views.py[line:432] nginx日志获取失败ConnectionError(<urllib3.connection.HTTPConnection object at 0x000000000433FC88>: Failed to establish a new connection: [WinError 10060] 由于连接方在一段时间后没有正确答复或连接的主机没有反应，连接尝试失败。) caused by: NewConnectionError(<urllib3.connection.HTTPConnection object at 0x000000000433FC88>: Failed to establish a new connection: [WinError 10060] 由于连接方在一段时间后没有正确答复或连接的主机没有反应，连接尝试失败。)
2017-08-02 14:51:24,564 ERROR    C:\Program Files\Python36\lib\site-packages\django\core\handlers\exception.py[line:124] Internal Server Error: /api/nginxLog/
Traceback (most recent call last):
  File "C:\Program Files\Python36\lib\site-packages\django\core\handlers\exception.py", line 39, in inner
    response = get_response(request)
  File "C:\Program Files\Python36\lib\site-packages\django\core\handlers\base.py", line 187, in _get_response
    response = self.process_exception_by_middleware(e, request)
  File "C:\Program Files\Python36\lib\site-packages\django\core\handlers\base.py", line 185, in _get_response
    response = wrapped_callback(request, *callback_args, **callback_kwargs)
  File "D:\project\opsweb\api\views.py", line 453, in nginxLog
    respon=result['aggregations']['map']['buckets']
UnboundLocalError: local variable 'result' referenced before assignment
2017-08-02 14:51:24,597 ERROR    D:\project\opsweb\api\views.py[line:432] nginx日志获取失败ConnectionError(<urllib3.connection.HTTPConnection object at 0x000000000433FE48>: Failed to establish a new connection: [WinError 10060] 由于连接方在一段时间后没有正确答复或连接的主机没有反应，连接尝试失败。) caused by: NewConnectionError(<urllib3.connection.HTTPConnection object at 0x000000000433FE48>: Failed to establish a new connection: [WinError 10060] 由于连接方在一段时间后没有正确答复或连接的主机没有反应，连接尝试失败。)
2017-08-02 14:51:24,599 ERROR    C:\Program Files\Python36\lib\site-packages\django\core\handlers\exception.py[line:124] Internal Server Error: /api/nginxLog/
Traceback (most recent call last):
  File "C:\Program Files\Python36\lib\site-packages\django\core\handlers\exception.py", line 39, in inner
    response = get_response(request)
  File "C:\Program Files\Python36\lib\site-packages\django\core\handlers\base.py", line 187, in _get_response
    response = self.process_exception_by_middleware(e, request)
  File "C:\Program Files\Python36\lib\site-packages\django\core\handlers\base.py", line 185, in _get_response
    response = wrapped_callback(request, *callback_args, **callback_kwargs)
  File "D:\project\opsweb\api\views.py", line 436, in nginxLog
    respon['message']=result['hits']['hits']
UnboundLocalError: local variable 'result' referenced before assignment
2017-08-02 14:51:24,618 ERROR    C:\Program Files\Python36\lib\site-packages\django\core\servers\basehttp.py[line:131] "POST /api/nginxLog/ HTTP/1.1" 500 14531
2017-08-02 14:51:24,637 ERROR    D:\project\opsweb\api\views.py[line:432] nginx日志获取失败ConnectionError(<urllib3.connection.HTTPConnection object at 0x000000000433FCF8>: Failed to establish a new connection: [WinError 10060] 由于连接方在一段时间后没有正确答复或连接的主机没有反应，连接尝试失败。) caused by: NewConnectionError(<urllib3.connection.HTTPConnection object at 0x000000000433FCF8>: Failed to establish a new connection: [WinError 10060] 由于连接方在一段时间后没有正确答复或连接的主机没有反应，连接尝试失败。)
2017-08-02 14:51:24,633 ERROR    C:\Program Files\Python36\lib\site-packages\django\core\servers\basehttp.py[line:131] "POST /api/nginxLog/ HTTP/1.1" 500 14524
2017-08-02 14:51:24,642 ERROR    C:\Program Files\Python36\lib\site-packages\django\core\handlers\exception.py[line:124] Internal Server Error: /api/nginxLog/
Traceback (most recent call last):
  File "C:\Program Files\Python36\lib\site-packages\django\core\handlers\exception.py", line 39, in inner
    response = get_response(request)
  File "C:\Program Files\Python36\lib\site-packages\django\core\handlers\base.py", line 187, in _get_response
    response = self.process_exception_by_middleware(e, request)
  File "C:\Program Files\Python36\lib\site-packages\django\core\handlers\base.py", line 185, in _get_response
    response = wrapped_callback(request, *callback_args, **callback_kwargs)
  File "D:\project\opsweb\api\views.py", line 456, in nginxLog
    for item in result['aggregations']['cityip']['buckets']:
UnboundLocalError: local variable 'result' referenced before assignment
2017-08-02 14:51:24,709 ERROR    C:\Program Files\Python36\lib\site-packages\django\core\servers\basehttp.py[line:131] "POST /api/nginxLog/ HTTP/1.1" 500 14540
2017-08-02 15:31:22,774 WARNING  C:\Program Files\Python36\lib\site-packages\django\core\handlers\base.py[line:152] Not Found: /favicon.ico
2017-08-02 15:31:22,778 WARNING  C:\Program Files\Python36\lib\site-packages\django\core\servers\basehttp.py[line:131] "GET /favicon.ico HTTP/1.1" 404 0
